Workbook

Sheet Resumo
A1: Resumo por tipologia de resíduo
A4: Tipologia | B4: Nº circuitos | C4: Circuitos sem viatura | D4: Semana · Manhã | E4: Semana · Tarde | F4: Semana · Noite | G4: Sábado | H4: Domingo | I4: Viaturas-turno (semana) | J4: Tripulantes-turno (semana) | K4: Total de Viaturas | L4: Total de RH
A5: Orgânicos | B5: =COUNTIF(Orgânicos!$A$5:$A$200,$A5) -> 7 | C5: =COUNTIFS(Orgânicos!$A$5:$A$200,$A5,Orgânicos!$N$5:$N$200,"Sem viatura atribuída") -> 1 | D5: =COUNTIFS(Base_Dados!$D$2:$D$500,$A5,Base_Dados!$A$2:$A$500,"Semana (2ª a 6ª)",Base_Dados!$B$2:$B$500,"Manhã") -> 4 | E5: =COUNTIFS(Base_Dados!$D$2:$D$500,$A5,Base_Dados!$A$2:$A$500,"Semana (2ª a 6ª)",Base_Dados!$B$2:$B$500,"Tarde") -> 3 | F5: =COUNTIFS(Base_Dados!$D$2:$D$500,$A5,Base_Dados!$A$2:$A$500,"Semana (2ª a 6ª)",Base_Dados!$B$2:$B$500,"Noite") -> 1 | G5: =COUNTIFS(Base_Dados!$D$2:$D$500,$A5,Base_Dados!$A$2:$A$500,"Sábado") -> 7 | H5: =COUNTIFS(Base_Dados!$D$2:$D$500,$A5,Base_Dados!$A$2:$A$500,"Domingo") -> 0 | I5: =SUM(D5:F5) -> 8 | J5: =SUMIFS(Base_Dados!$F$2:$F$500,Base_Dados!$D$2:$D$500,$A5,Base_Dados!$A$2:$A$500,"Semana (2ª a 6ª)") -> 23 | K5: 6 | L5: 12
A6: Indiferenciados | B6: =COUNTIF(Indiferenciados!$A$5:$A$200,$A6) -> 24 | C6: =COUNTIFS(Indiferenciados!$A$5:$A$200,$A6,Indiferenciados!$N$5:$N$200,"Sem viatura atribuída") -> 8 | D6: =COUNTIFS(Base_Dados!$D$2:$D$500,$A6,Base_Dados!$A$2:$A$500,"Semana (2ª a 6ª)",Base_Dados!$B$2:$B$500,"Manhã") -> 14 | E6: =COUNTIFS(Base_Dados!$D$2:$D$500,$A6,Base_Dados!$A$2:$A$500,"Semana (2ª a 6ª)",Base_Dados!$B$2:$B$500,"Tarde") -> 4 | F6: =COUNTIFS(Base_Dados!$D$2:$D$500,$A6,Base_Dados!$A$2:$A$500,"Semana (2ª a 6ª)",Base_Dados!$B$2:$B$500,"Noite") -> 0 | G6: =COUNTIFS(Base_Dados!$D$2:$D$500,$A6,Base_Dados!$A$2:$A$500,"Sábado") -> 18 | H6: =COUNTIFS(Base_Dados!$D$2:$D$500,$A6,Base_Dados!$A$2:$A$500,"Domingo") -> 1 | I6: =SUM(D6:F6) -> 18 | J6: =SUMIFS(Base_Dados!$F$2:$F$500,Base_Dados!$D$2:$D$500,$A6,Base_Dados!$A$2:$A$500,"Semana (2ª a 6ª)") -> 48 | K6: 24 | L6: 72 | M6: Dados Miguel
A7: Recicláveis | B7: =COUNTIF(Recicláveis!$A$5:$A$200,$A7) -> 3 | C7: =COUNTIFS(Recicláveis!$A$5:$A$200,$A7,Recicláveis!$N$5:$N$200,"Sem viatura atribuída") -> 0 | D7: =COUNTIFS(Base_Dados!$D$2:$D$500,$A7,Base_Dados!$A$2:$A$500,"Semana (2ª a 6ª)",Base_Dados!$B$2:$B$500,"Manhã") -> 1 | E7: =COUNTIFS(Base_Dados!$D$2:$D$500,$A7,Base_Dados!$A$2:$A$500,"Semana (2ª a 6ª)",Base_Dados!$B$2:$B$500,"Tarde") -> 4 | F7: =COUNTIFS(Base_Dados!$D$2:$D$500,$A7,Base_Dados!$A$2:$A$500,"Semana (2ª a 6ª)",Base_Dados!$B$2:$B$500,"Noite") -> 0 | G7: =COUNTIFS(Base_Dados!$D$2:$D$500,$A7,Base_Dados!$A$2:$A$500,"Sábado") -> 3 | H7: =COUNTIFS(Base_Dados!$D$2:$D$500,$A7,Base_Dados!$A$2:$A$500,"Domingo") -> 0 | I7: =SUM(D7:F7) -> 5 | J7: =SUMIFS(Base_Dados!$F$2:$F$500,Base_Dados!$D$2:$D$500,$A7,Base_Dados!$A$2:$A$500,"Semana (2ª a 6ª)") -> 11 | K7: 4 | L7: 10
A8: Volumosos (Monstros) | B8: =COUNTIF(Volumosos!$A$5:$A$200,$A8) -> 1 | C8: =COUNTIFS(Volumosos!$A$5:$A$200,$A8,Volumosos!$N$5:$N$200,"Sem viatura atribuída") -> 0 | D8: =COUNTIFS(Base_Dados!$D$2:$D$500,$A8,Base_Dados!$A$2:$A$500,"Semana (2ª a 6ª)",Base_Dados!$B$2:$B$500,"Manhã") -> 4 | E8: =COUNTIFS(Base_Dados!$D$2:$D$500,$A8,Base_Dados!$A$2:$A$500,"Semana (2ª a 6ª)",Base_Dados!$B$2:$B$500,"Tarde") -> 2 | F8: =COUNTIFS(Base_Dados!$D$2:$D$500,$A8,Base_Dados!$A$2:$A$500,"Semana (2ª a 6ª)",Base_Dados!$B$2:$B$500,"Noite") -> 0 | G8: =COUNTIFS(Base_Dados!$D$2:$D$500,$A8,Base_Dados!$A$2:$A$500,"Sábado") -> 5 | H8: =COUNTIFS(Base_Dados!$D$2:$D$500,$A8,Base_Dados!$A$2:$A$500,"Domingo") -> 0 | I8: =SUM(D8:F8) -> 6 | J8: =SUMIFS(Base_Dados!$F$2:$F$500,Base_Dados!$D$2:$D$500,$A8,Base_Dados!$A$2:$A$500,"Semana (2ª a 6ª)") -> 7 | K8: - | L8: -
A9: PAYT | B9: =COUNTIF('Outros serviços'!$A$5:$A$200,$A9) -> 1 | C9: =COUNTIFS('Outros serviços'!$A$5:$A$200,$A9,'Outros serviços'!$N$5:$N$200,"Sem viatura atribuída") -> 0 | D9: =COUNTIFS(Base_Dados!$D$2:$D$500,$A9,Base_Dados!$A$2:$A$500,"Semana (2ª a 6ª)",Base_Dados!$B$2:$B$500,"Manhã") -> 1 | E9: =COUNTIFS(Base_Dados!$D$2:$D$500,$A9,Base_Dados!$A$2:$A$500,"Semana (2ª a 6ª)",Base_Dados!$B$2:$B$500,"Tarde") -> 1 | F9: =COUNTIFS(Base_Dados!$D$2:$D$500,$A9,Base_Dados!$A$2:$A$500,"Semana (2ª a 6ª)",Base_Dados!$B$2:$B$500,"Noite") -> 2 | G9: =COUNTIFS(Base_Dados!$D$2:$D$500,$A9,Base_Dados!$A$2:$A$500,"Sábado") -> 4 | H9: =COUNTIFS(Base_Dados!$D$2:$D$500,$A9,Base_Dados!$A$2:$A$500,"Domingo") -> 4 | I9: =SUM(D9:F9) -> 4 | J9: =SUMIFS(Base_Dados!$F$2:$F$500,Base_Dados!$D$2:$D$500,$A9,Base_Dados!$A$2:$A$500,"Semana (2ª a 6ª)") -> 6 | K9: - | L9: -
A10: Serviços de apoio | B10: =COUNTIF('Outros serviços'!$A$5:$A$200,$A10) -> 2 | C10: =COUNTIFS('Outros serviços'!$A$5:$A$200,$A10,'Outros serviços'!$N$5:$N$200,"Sem viatura atribuída") -> 0 | D10: =COUNTIFS(Base_Dados!$D$2:$D$500,$A10,Base_Dados!$A$2:$A$500,"Semana (2ª a 6ª)",Base_Dados!$B$2:$B$500,"Manhã") -> 2 | E10: =COUNTIFS(Base_Dados!$D$2:$D$500,$A10,Base_Dados!$A$2:$A$500,"Semana (2ª a 6ª)",Base_Dados!$B$2:$B$500,"Tarde") -> 1 | F10: =COUNTIFS(Base_Dados!$D$2:$D$500,$A10,Base_Dados!$A$2:$A$500,"Semana (2ª a 6ª)",Base_Dados!$B$2:$B$500,"Noite") -> 0 | G10: =COUNTIFS(Base_Dados!$D$2:$D$500,$A10,Base_Dados!$A$2:$A$500,"Sábado") -> 1 | H10: =COUNTIFS(Base_Dados!$D$2:$D$500,$A10,Base_Dados!$A$2:$A$500,"Domingo") -> 0 | I10: =SUM(D10:F10) -> 3 | J10: =SUMIFS(Base_Dados!$F$2:$F$500,Base_Dados!$D$2:$D$500,$A10,Base_Dados!$A$2:$A$500,"Semana (2ª a 6ª)") -> 3 | K10: - | L10: -
A11: A confirmar | B11: =COUNTIF('Outros serviços'!$A$5:$A$200,$A11) -> 2 | C11: =COUNTIFS('Outros serviços'!$A$5:$A$200,$A11,'Outros serviços'!$N$5:$N$200,"Sem viatura atribuída") -> 0 | D11: =COUNTIFS(Base_Dados!$D$2:$D$500,$A11,Base_Dados!$A$2:$A$500,"Semana (2ª a 6ª)",Base_Dados!$B$2:$B$500,"Manhã") -> 1 | E11: =COUNTIFS(Base_Dados!$D$2:$D$500,$A11,Base_Dados!$A$2:$A$500,"Semana (2ª a 6ª)",Base_Dados!$B$2:$B$500,"Tarde") -> 0 | F11: =COUNTIFS(Base_Dados!$D$2:$D$500,$A11,Base_Dados!$A$2:$A$500,"Semana (2ª a 6ª)",Base_Dados!$B$2:$B$500,"Noite") -> 0 | G11: =COUNTIFS(Base_Dados!$D$2:$D$500,$A11,Base_Dados!$A$2:$A$500,"Sábado") -> 1 | H11: =COUNTIFS(Base_Dados!$D$2:$D$500,$A11,Base_Dados!$A$2:$A$500,"Domingo") -> 1 | I11: =SUM(D11:F11) -> 1 | J11: =SUMIFS(Base_Dados!$F$2:$F$500,Base_Dados!$D$2:$D$500,$A11,Base_Dados!$A$2:$A$500,"Semana (2ª a 6ª)") -> 3 | K11: - | L11: -
A12: TOTAL | B12: =SUM(B5:B11) -> 40 | C12: =SUM(C5:C11) -> 9 | D12: =SUM(D5:D11) -> 27 | E12: =SUM(E5:E11) -> 15 | F12: =SUM(F5:F11) -> 3 | G12: =SUM(G5:G11) -> 39 | H12: =SUM(H5:H11) -> 6 | I12: =SUM(I5:I11) -> 45 | J12: =SUM(J5:J11) -> 101

Sheet Orgânicos
A1: Circuitos · Orgânicos
A4: Tipologia | B4: Circuito | C4: Tipo de recolha | D4: Localidades | E4: Dias de recolha | F4: Cód. viatura (ficheiro circuitos) | G4: Semana · Manhã | H4: Semana · Tarde | I4: Semana · Noite | J4: Sábado | K4: Domingo | L4: Nº afetações (semana) | M4: Nº afetações (total) | N4: Estado | O4: Observação
A5: Orgânicos | B5: BIO 1 | C5: PAP | D5: Centro histórico | E5: Todos os dias Manhã e tarde | F5: V1 | G5: {=_xlfn.TEXTJOIN(", ",TRUE(),IF((Base_Dados!$C$2:$C$500=$B5)*(Base_Dados!$A$2:$A$500="Semana (2ª a 6ª)")*(Base_Dados!$B$2:$B$500="Manhã"),Base_Dados!$E$2:$E$500,""))} | H5: {=_xlfn.TEXTJOIN(", ",TRUE(),IF((Base_Dados!$C$2:$C$500=$B5)*(Base_Dados!$A$2:$A$500="Semana (2ª a 6ª)")*(Base_Dados!$B$2:$B$500="Tarde"),Base_Dados!$E$2:$E$500,""))} -> AR-93-SQ | I5: {=_xlfn.TEXTJOIN(", ",TRUE(),IF((Base_Dados!$C$2:$C$500=$B5)*(Base_Dados!$A$2:$A$500="Semana (2ª a 6ª)")*(Base_Dados!$B$2:$B$500="Noite"),Base_Dados!$E$2:$E$500,""))} -> AR-81-SQ | J5: {=_xlfn.TEXTJOIN(", ",TRUE(),IF((Base_Dados!$C$2:$C$500=$B5)*(Base_Dados!$A$2:$A$500="Sábado"),Base_Dados!$E$2:$E$500&" ("&Base_Dados!$B$2:$B$500&")",""))} -> AR-81-SQ (Tarde), AR-81-SQ (Noite) | K5: {=_xlfn.TEXTJOIN(", ",TRUE(),IF((Base_Dados!$C$2:$C$500=$B5)*(Base_Dados!$A$2:$A$500="Domingo"),Base_Dados!$E$2:$E$500&" ("&Base_Dados!$B$2:$B$500&")",""))} | L5: =COUNTIFS(Base_Dados!$C$2:$C$500,$B5,Base_Dados!$A$2:$A$500,"Semana (2ª a 6ª)") -> 2 | M5: =COUNTIF(Base_Dados!$C$2:$C$500,$B5) -> 4 | N5: =IF(M5=0,"Sem viatura atribuída",IF(L5=0,"Só ao fim de semana","OK")) -> OK
A6: Orgânicos | B6: BIO 2 | C6: Contentores | D6: HORECA Cemitérios Contentores 1000L Taipas e Creixomil | E6: Todos os dias Manhã e tarde | F6: V2 | G6: {=_xlfn.TEXTJOIN(", ",TRUE(),IF((Base_Dados!$C$2:$C$500=$B6)*(Base_Dados!$A$2:$A$500="Semana (2ª a 6ª)")*(Base_Dados!$B$2:$B$500="Manhã"),Base_Dados!$E$2:$E$500,""))} | H6: {=_xlfn.TEXTJOIN(", ",TRUE(),IF((Base_Dados!$C$2:$C$500=$B6)*(Base_Dados!$A$2:$A$500="Semana (2ª a 6ª)")*(Base_Dados!$B$2:$B$500="Tarde"),Base_Dados!$E$2:$E$500,""))} -> AR-81-SQ | I6: {=_xlfn.TEXTJOIN(", ",TRUE(),IF((Base_Dados!$C$2:$C$500=$B6)*(Base_Dados!$A$2:$A$500="Semana (2ª a 6ª)")*(Base_Dados!$B$2:$B$500="Noite"),Base_Dados!$E$2:$E$500,""))} | J6: {=_xlfn.TEXTJOIN(", ",TRUE(),IF((Base_Dados!$C$2:$C$500=$B6)*(Base_Dados!$A$2:$A$500="Sábado"),Base_Dados!$E$2:$E$500&" ("&Base_Dados!$B$2:$B$500&")",""))} -> AR-93-SQ (Tarde) | K6: {=_xlfn.TEXTJOIN(", ",TRUE(),IF((Base_Dados!$C$2:$C$500=$B6)*(Base_Dados!$A$2:$A$500="Domingo"),Base_Dados!$E$2:$E$500&" ("&Base_Dados!$B$2:$B$500&")",""))} | L6: =COUNTIFS(Base_Dados!$C$2:$C$500,$B6,Base_Dados!$A$2:$A$500,"Semana (2ª a 6ª)") -> 1 | M6: =COUNTIF(Base_Dados!$C$2:$C$500,$B6) -> 2 | N6: =IF(M6=0,"Sem viatura atribuída",IF(L6=0,"Só ao fim de semana","OK")) -> OK
A7: Orgânicos | B7: BIO 3 | C7: Contentores | D7: Todos os cemitérios do concelho | E7: Todos os dias | F7: V3 | G7: {=_xlfn.TEXTJOIN(", ",TRUE(),IF((Base_Dados!$C$2:$C$500=$B7)*(Base_Dados!$A$2:$A$500="Semana (2ª a 6ª)")*(Base_Dados!$B$2:$B$500="Manhã"),Base_Dados!$E$2:$E$500,""))} -> 60-93-ZG | H7: {=_xlfn.TEXTJOIN(", ",TRUE(),IF((Base_Dados!$C$2:$C$500=$B7)*(Base_Dados!$A$2:$A$500="Semana (2ª a 6ª)")*(Base_Dados!$B$2:$B$500="Tarde"),Base_Dados!$E$2:$E$500,""))} -> AS-75-SG | I7: {=_xlfn.TEXTJOIN(", ",TRUE(),IF((Base_Dados!$C$2:$C$500=$B7)*(Base_Dados!$A$2:$A$500="Semana (2ª a 6ª)")*(Base_Dados!$B$2:$B$500="Noite"),Base_Dados!$E$2:$E$500,""))} | J7: {=_xlfn.TEXTJOIN(", ",TRUE(),IF((Base_Dados!$C$2:$C$500=$B7)*(Base_Dados!$A$2:$A$500="Sábado"),Base_Dados!$E$2:$E$500&" ("&Base_Dados!$B$2:$B$500&")",""))} -> 60-93-ZG (Manhã), AS-75-SG (Tarde) | K7: {=_xlfn.TEXTJOIN(", ",TRUE(),IF((Base_Dados!$C$2:$C$500=$B7)*(Base_Dados!$A$2:$A$500="Domingo"),Base_Dados!$E$2:$E$500&" ("&Base_Dados!$B$2:$B$500&")",""))} | L7: =COUNTIFS(Base_Dados!$C$2:$C$500,$B7,Base_Dados!$A$2:$A$500,"Semana (2ª a 6ª)") -> 2 | M7: =COUNTIF(Base_Dados!$C$2:$C$500,$B7) -> 4 | N7: =IF(M7=0,"Sem viatura atribuída",IF(L7=0,"Só ao fim de semana","OK")) -> OK
A8: Orgânicos | B8: BIO 4 | C8: Contentores | D8: Cidade Costa Urgezes Azúrem Creixomil Campelos | F8: V1 | G8: {=_xlfn.TEXTJOIN(", ",TRUE(),IF((Base_Dados!$C$2:$C$500=$B8)*(Base_Dados!$A$2:$A$500="Semana (2ª a 6ª)")*(Base_Dados!$B$2:$B$500="Manhã"),Base_Dados!$E$2:$E$500,""))} -> AR-93-SQ | H8: {=_xlfn.TEXTJOIN(", ",TRUE(),IF((Base_Dados!$C$2:$C$500=$B8)*(Base_Dados!$A$2:$A$500="Semana (2ª a 6ª)")*(Base_Dados!$B$2:$B$500="Tarde"),Base_Dados!$E$2:$E$500,""))} | I8: {=_xlfn.TEXTJOIN(", ",TRUE(),IF((Base_Dados!$C$2:$C$500=$B8)*(Base_Dados!$A$2:$A$500="Semana (2ª a 6ª)")*(Base_Dados!$B$2:$B$500="Noite"),Base_Dados!$E$2:$E$500,""))} | J8: {=_xlfn.TEXTJOIN(", ",TRUE(),IF((Base_Dados!$C$2:$C$500=$B8)*(Base_Dados!$A$2:$A$500="Sábado"),Base_Dados!$E$2:$E$500&" ("&Base_Dados!$B$2:$B$500&")",""))} | K8: {=_xlfn.TEXTJOIN(", ",TRUE(),IF((Base_Dados!$C$2:$C$500=$B8)*(Base_Dados!$A$2:$A$500="Domingo"),Base_Dados!$E$2:$E$500&" ("&Base_Dados!$B$2:$B$500&")",""))} | L8: =COUNTIFS(Base_Dados!$C$2:$C$500,$B8,Base_Dados!$A$2:$A$500,"Semana (2ª a 6ª)") -> 1 | M8: =COUNTIF(Base_Dados!$C$2:$C$500,$B8) -> 1 | N8: =IF(M8=0,"Sem viatura atribuída",IF(L8=0,"Só ao fim de semana","OK")) -> OK
A9: Orgânicos | B9: BIO 5 | C9: Contentores | D9: Aldão (compactador) | G9: {=_xlfn.TEXTJOIN(", ",TRUE(),IF((Base_Dados!$C$2:$C$500=$B9)*(Base_Dados!$A$2:$A$500="Semana (2ª a 6ª)")*(Base_Dados!$B$2:$B$500="Manhã"),Base_Dados!$E$2:$E$500,""))} | H9: {=_xlfn.TEXTJOIN(", ",TRUE(),IF((Base_Dados!$C$2:$C$500=$B9)*(Base_Dados!$A$2:$A$500="Semana (2ª a 6ª)")*(Base_Dados!$B$2:$B$500="Tarde"),Base_Dados!$E$2:$E$500,""))} | I9: {=_xlfn.TEXTJOIN(", ",TRUE(),IF((Base_Dados!$C$2:$C$500=$B9)*(Base_Dados!$A$2:$A$500="Semana (2ª a 6ª)")*(Base_Dados!$B$2:$B$500="Noite"),Base_Dados!$E$2:$E$500,""))} | J9: {=_xlfn.TEXTJOIN(", ",TRUE(),IF((Base_Dados!$C$2:$C$500=$B9)*(Base_Dados!$A$2:$A$500="Sábado"),Base_Dados!$E$2:$E$500&" ("&Base_Dados!$B$2:$B$500&")",""))} | K9: {=_xlfn.TEXTJOIN(", ",TRUE(),IF((Base_Dados!$C$2:$C$500=$B9)*(Base_Dados!$A$2:$A$500="Domingo"),Base_Dados!$E$2:$E$500&" ("&Base_Dados!$B$2:$B$500&")",""))} | L9: =COUNTIFS(Base_Dados!$C$2:$C$500,$B9,Base_Dados!$A$2:$A$500,"Semana (2ª a 6ª)") -> 0 | M9: =COUNTIF(Base_Dados!$C$2:$C$500,$B9) -> 0 | N9: =IF(M9=0,"Sem viatura atribuída",IF(L9=0,"Só ao fim de semana","OK")) -> Sem viatura atribuída
A10: Orgânicos | B10: BIO 6 | C10: Contentores | D10: Ponte Fermentões | E10: Segunda-feria Sexta-feira | F10: V4 | G10: {=_xlfn.TEXTJOIN(", ",TRUE(),IF((Base_Dados!$C$2:$C$500=$B10)*(Base_Dados!$A$2:$A$500="Semana (2ª a 6ª)")*(Base_Dados!$B$2:$B$500="Manhã"),Base_Dados!$E$2:$E$500,""))} -> AN-50-LT | H10: {=_xlfn.TEXTJOIN(", ",TRUE(),IF((Base_Dados!$C$2:$C$500=$B10)*(Base_Dados!$A$2:$A$500="Semana (2ª a 6ª)")*(Base_Dados!$B$2:$B$500="Tarde"),Base_Dados!$E$2:$E$500,""))} | I10: {=_xlfn.TEXTJOIN(", ",TRUE(),IF((Base_Dados!$C$2:$C$500=$B10)*(Base_Dados!$A$2:$A$500="Semana (2ª a 6ª)")*(Base_Dados!$B$2:$B$500="Noite"),Base_Dados!$E$2:$E$500,""))} | J10: {=_xlfn.TEXTJOIN(", ",TRUE(),IF((Base_Dados!$C$2:$C$500=$B10)*(Base_Dados!$A$2:$A$500="Sábado"),Base_Dados!$E$2:$E$500&" ("&Base_Dados!$B$2:$B$500&")",""))} | K10: {=_xlfn.TEXTJOIN(", ",TRUE(),IF((Base_Dados!$C$2:$C$500=$B10)*(Base_Dados!$A$2:$A$500="Domingo"),Base_Dados!$E$2:$E$500&" ("&Base_Dados!$B$2:$B$500&")",""))} | L10: =COUNTIFS(Base_Dados!$C$2:$C$500,$B10,Base_Dados!$A$2:$A$500,"Semana (2ª a 6ª)") -> 1 | M10: =COUNTIF(Base_Dados!$C$2:$C$500,$B10) -> 1 | N10: =IF(M10=0,"Sem viatura atribuída",IF(L10=0,"Só ao fim de semana","OK")) -> OK
A11: Orgânicos | B11: BIO (s/ nº) | G11: {=_xlfn.TEXTJOIN(", ",TRUE(),IF((Base_Dados!$C$2:$C$500=$B11)*(Base_Dados!$A$2:$A$500="Semana (2ª a 6ª)")*(Base_Dados!$B$2:$B$500="Manhã"),Base_Dados!$E$2:$E$500,""))} -> 58-PF-10 | H11: {=_xlfn.TEXTJOIN(", ",TRUE(),IF((Base_Dados!$C$2:$C$500=$B11)*(Base_Dados!$A$2:$A$500="Semana (2ª a 6ª)")*(Base_Dados!$B$2:$B$500="Tarde"),Base_Dados!$E$2:$E$500,""))} | I11: {=_xlfn.TEXTJOIN(", ",TRUE(),IF((Base_Dados!$C$2:$C$500=$B11)*(Base_Dados!$A$2:$A$500="Semana (2ª a 6ª)")*(Base_Dados!$B$2:$B$500="Noite"),Base_Dados!$E$2:$E$500,""))} | J11: {=_xlfn.TEXTJOIN(", ",TRUE(),IF((Base_Dados!$C$2:$C$500=$B11)*(Base_Dados!$A$2:$A$500="Sábado"),Base_Dados!$E$2:$E$500&" ("&Base_Dados!$B$2:$B$500&")",""))} -> AN-50-LT (Manhã), AR-93-SQ (Manhã) | K11: {=_xlfn.TEXTJOIN(", ",TRUE(),IF((Base_Dados!$C$2:$C$500=$B11)*(Base_Dados!$A$2:$A$500="Domingo"),Base_Dados!$E$2:$E$500&" ("&Base_Dados!$B$2:$B$500&")",""))} | L11: =COUNTIFS(Base_Dados!$C$2:$C$500,$B11,Base_Dados!$A$2:$A$500,"Semana (2ª a 6ª)") -> 1 | M11: =COUNTIF(Base_Dados!$C$2:$C$500,$B11) -> 3 | N11: =IF(M11=0,"Sem viatura atribuída",IF(L11=0,"Só ao fim de semana","OK")) -> OK | O11: Escrito só "Bio" no planeamento. Confirmar qual circuito BIO.

Sheet Indiferenciados
A1: Circuitos · Indiferenciados
A4: Tipologia | B4: Circuito | C4: Tipo de recolha | D4: Localidades | E4: Dias de recolha | F4: Cód. viatura (ficheiro circuitos) | G4: Semana · Manhã | H4: Semana · Tarde | I4: Semana · Noite | J4: Sábado | K4: Domingo | L4: Nº afetações (semana) | M4: Nº afetações (total) | N4: Estado | O4: Observação
A5: Indiferenciados | B5: C1 | C5: Moloks | D5: Costa Azurém Moreira de Cónegos Mesão Frio São Torcato | E5: Conforme planeamento | G5: {=_xlfn.TEXTJOIN(", ",TRUE(),IF((Base_Dados!$C$2:$C$500=$B5)*(Base_Dados!$A$2:$A$500="Semana (2ª a 6ª)")*(Base_Dados!$B$2:$B$500="Manhã"),Base_Dados!$E$2:$E$500,""))} -> 69-TJ-24 | H5: {=_xlfn.TEXTJOIN(", ",TRUE(),IF((Base_Dados!$C$2:$C$500=$B5)*(Base_Dados!$A$2:$A$500="Semana (2ª a 6ª)")*(Base_Dados!$B$2:$B$500="Tarde"),Base_Dados!$E$2:$E$500,""))} -> AV-32-SV | I5: {=_xlfn.TEXTJOIN(", ",TRUE(),IF((Base_Dados!$C$2:$C$500=$B5)*(Base_Dados!$A$2:$A$500="Semana (2ª a 6ª)")*(Base_Dados!$B$2:$B$500="Noite"),Base_Dados!$E$2:$E$500,""))} | J5: {=_xlfn.TEXTJOIN(", ",TRUE(),IF((Base_Dados!$C$2:$C$500=$B5)*(Base_Dados!$A$2:$A$500="Sábado"),Base_Dados!$E$2:$E$500&" ("&Base_Dados!$B$2:$B$500&")",""))} -> 65-RB-29 (Manhã), AV-32-SV (Tarde) | K5: {=_xlfn.TEXTJOIN(", ",TRUE(),IF((Base_Dados!$C$2:$C$500=$B5)*(Base_Dados!$A$2:$A$500="Domingo"),Base_Dados!$E$2:$E$500&" ("&Base_Dados!$B$2:$B$500&")",""))} -> AJ-49-UO (Manhã) | L5: =COUNTIFS(Base_Dados!$C$2:$C$500,$B5,Base_Dados!$A$2:$A$500,"Semana (2ª a 6ª)") -> 2 | M5: =COUNTIF(Base_Dados!$C$2:$C$500,$B5) -> 5 | N5: =IF(M5=0,"Sem viatura atribuída",IF(L5=0,"Só ao fim de semana","OK")) -> OK
A6: Indiferenciados | B6: C2 | C6: Moloks | D6: Cidade Costa Senhora da Conceição | E6: Conforme planeamento | G6: {=_xlfn.TEXTJOIN(", ",TRUE(),IF((Base_Dados!$C$2:$C$500=$B6)*(Base_Dados!$A$2:$A$500="Semana (2ª a 6ª)")*(Base_Dados!$B$2:$B$500="Manhã"),Base_Dados!$E$2:$E$500,""))} -> CA-27-DS | H6: {=_xlfn.TEXTJOIN(", ",TRUE(),IF((Base_Dados!$C$2:$C$500=$B6)*(Base_Dados!$A$2:$A$500="Semana (2ª a 6ª)")*(Base_Dados!$B$2:$B$500="Tarde"),Base_Dados!$E$2:$E$500,""))} | I6: {=_xlfn.TEXTJOIN(", ",TRUE(),IF((Base_Dados!$C$2:$C$500=$B6)*(Base_Dados!$A$2:$A$500="Semana (2ª a 6ª)")*(Base_Dados!$B$2:$B$500="Noite"),Base_Dados!$E$2:$E$500,""))} | J6: {=_xlfn.TEXTJOIN(", ",TRUE(),IF((Base_Dados!$C$2:$C$500=$B6)*(Base_Dados!$A$2:$A$500="Sábado"),Base_Dados!$E$2:$E$500&" ("&Base_Dados!$B$2:$B$500&")",""))} -> CA-27-DS (Manhã) | K6: {=_xlfn.TEXTJOIN(", ",TRUE(),IF((Base_Dados!$C$2:$C$500=$B6)*(Base_Dados!$A$2:$A$500="Domingo"),Base_Dados!$E$2:$E$500&" ("&Base_Dados!$B$2:$B$500&")",""))} | L6: =COUNTIFS(Base_Dados!$C$2:$C$500,$B6,Base_Dados!$A$2:$A$500,"Semana (2ª a 6ª)") -> 1 | M6: =COUNTIF(Base_Dados!$C$2:$C$500,$B6) -> 2 | N6: =IF(M6=0,"Sem viatura atribuída",IF(L6=0,"Só ao fim de semana","OK")) -> OK
A7: Indiferenciados | B7: C3 | C7: Moloks | D7: Fermentões Caldelas Barco Santo Eufémia Ponte Sande S. Martinho Prazins Souto | E7: Conforme planeamento | G7: {=_xlfn.TEXTJOIN(", ",TRUE(),IF((Base_Dados!$C$2:$C$500=$B7)*(Base_Dados!$A$2:$A$500="Semana (2ª a 6ª)")*(Base_Dados!$B$2:$B$500="Manhã"),Base_Dados!$E$2:$E$500,""))} | H7: {=_xlfn.TEXTJOIN(", ",TRUE(),IF((Base_Dados!$C$2:$C$500=$B7)*(Base_Dados!$A$2:$A$500="Semana (2ª a 6ª)")*(Base_Dados!$B$2:$B$500="Tarde"),Base_Dados!$E$2:$E$500,""))} -> AJ-49-UO | I7: {=_xlfn.TEXTJOIN(", ",TRUE(),IF((Base_Dados!$C$2:$C$500=$B7)*(Base_Dados!$A$2:$A$500="Semana (2ª a 6ª)")*(Base_Dados!$B$2:$B$500="Noite"),Base_Dados!$E$2:$E$500,""))} | J7: {=_xlfn.TEXTJOIN(", ",TRUE(),IF((Base_Dados!$C$2:$C$500=$B7)*(Base_Dados!$A$2:$A$500="Sábado"),Base_Dados!$E$2:$E$500&" ("&Base_Dados!$B$2:$B$500&")",""))} -> AJ-49-UO (Tarde) | K7: {=_xlfn.TEXTJOIN(", ",TRUE(),IF((Base_Dados!$C$2:$C$500=$B7)*(Base_Dados!$A$2:$A$500="Domingo"),Base_Dados!$E$2:$E$500&" ("&Base_Dados!$B$2:$B$500&")",""))} | L7: =COUNTIFS(Base_Dados!$C$2:$C$500,$B7,Base_Dados!$A$2:$A$500,"Semana (2ª a 6ª)") -> 1 | M7: =COUNTIF(Base_Dados!$C$2:$C$500,$B7) -> 2 | N7: =IF(M7=0,"Sem viatura atribuída",IF(L7=0,"Só ao fim de semana","OK")) -> OK
A8: Indiferenciados | B8: C4 | C8: Moloks | D8: Urgezes Selho Campelos Ronfe Serzedelo Gandarela Silvares Brito Gondar Guardizela | E8: Conforme planeamento | G8: {=_xlfn.TEXTJOIN(", ",TRUE(),IF((Base_Dados!$C$2:$C$500=$B8)*(Base_Dados!$A$2:$A$500="Semana (2ª a 6ª)")*(Base_Dados!$B$2:$B$500="Manhã"),Base_Dados!$E$2:$E$500,""))} | H8: {=_xlfn.TEXTJOIN(", ",TRUE(),IF((Base_Dados!$C$2:$C$500=$B8)*(Base_Dados!$A$2:$A$500="Semana (2ª a 6ª)")*(Base_Dados!$B$2:$B$500="Tarde"),Base_Dados!$E$2:$E$500,""))} -> 69-TJ-24 | I8: {=_xlfn.TEXTJOIN(", ",TRUE(),IF((Base_Dados!$C$2:$C$500=$B8)*(Base_Dados!$A$2:$A$500="Semana (2ª a 6ª)")*(Base_Dados!$B$2:$B$500="Noite"),Base_Dados!$E$2:$E$500,""))} | J8: {=_xlfn.TEXTJOIN(", ",TRUE(),IF((Base_Dados!$C$2:$C$500=$B8)*(Base_Dados!$A$2:$A$500="Sábado"),Base_Dados!$E$2:$E$500&" ("&Base_Dados!$B$2:$B$500&")",""))} -> 69-TJ-24 (Tarde) | K8: {=_xlfn.TEXTJOIN(", ",TRUE(),IF((Base_Dados!$C$2:$C$500=$B8)*(Base_Dados!$A$2:$A$500="Domingo"),Base_Dados!$E$2:$E$500&" ("&Base_Dados!$B$2:$B$500&")",""))} | L8: =COUNTIFS(Base_Dados!$C$2:$C$500,$B8,Base_Dados!$A$2:$A$500,"Semana (2ª a 6ª)") -> 1 | M8: =COUNTIF(Base_Dados!$C$2:$C$500,$B8) -> 2 | N8: =IF(M8=0,"Sem viatura atribuída",IF(L8=0,"Só ao fim de semana","OK")) -> OK
A9: Indiferenciados | B9: C5 | C9: Moloks | D9: Creixomil (zona alta) | E9: Conforme planeamento | G9: {=_xlfn.TEXTJOIN(", ",TRUE(),IF((Base_Dados!$C$2:$C$500=$B9)*(Base_Dados!$A$2:$A$500="Semana (2ª a 6ª)")*(Base_Dados!$B$2:$B$500="Manhã"),Base_Dados!$E$2:$E$500,""))} -> AV-32-SV | H9: {=_xlfn.TEXTJOIN(", ",TRUE(),IF((Base_Dados!$C$2:$C$500=$B9)*(Base_Dados!$A$2:$A$500="Semana (2ª a 6ª)")*(Base_Dados!$B$2:$B$500="Tarde"),Base_Dados!$E$2:$E$500,""))} | I9: {=_xlfn.TEXTJOIN(", ",TRUE(),IF((Base_Dados!$C$2:$C$500=$B9)*(Base_Dados!$A$2:$A$500="Semana (2ª a 6ª)")*(Base_Dados!$B$2:$B$500="Noite"),Base_Dados!$E$2:$E$500,""))} | J9: {=_xlfn.TEXTJOIN(", ",TRUE(),IF((Base_Dados!$C$2:$C$500=$B9)*(Base_Dados!$A$2:$A$500="Sábado"),Base_Dados!$E$2:$E$500&" ("&Base_Dados!$B$2:$B$500&")",""))} -> AV-32-SV (Manhã) | K9: {=_xlfn.TEXTJOIN(", ",TRUE(),IF((Base_Dados!$C$2:$C$500=$B9)*(Base_Dados!$A$2:$A$500="Domingo"),Base_Dados!$E$2:$E$500&" ("&Base_Dados!$B$2:$B$500&")",""))} | L9: =COUNTIFS(Base_Dados!$C$2:$C$500,$B9,Base_Dados!$A$2:$A$500,"Semana (2ª a 6ª)") -> 1 | M9: =COUNTIF(Base_Dados!$C$2:$C$500,$B9) -> 2 | N9: =IF(M9=0,"Sem viatura atribuída",IF(L9=0,"Só ao fim de semana","OK")) -> OK
A10: Indiferenciados | B10: C6 | C10: Moloks | D10: Urgezes, Abação, Creixomil (zona baixa), Penha, Polvoreira, Conde, Nespereira e Lordelo | E10: Conforme planeamento | G10: {=_xlfn.TEXTJOIN(", ",TRUE(),IF((Base_Dados!$C$2:$C$500=$B10)*(Base_Dados!$A$2:$A$500="Semana (2ª a 6ª)")*(Base_Dados!$B$2:$B$500="Manhã"),Base_Dados!$E$2:$E$500,""))} -> 24-ZZ-64 | H10: {=_xlfn.TEXTJOIN(", ",TRUE(),IF((Base_Dados!$C$2:$C$500=$B10)*(Base_Dados!$A$2:$A$500="Semana (2ª a 6ª)")*(Base_Dados!$B$2:$B$500="Tarde"),Base_Dados!$E$2:$E$500,""))} -> CA-27-DS | I10: {=_xlfn.TEXTJOIN(", ",TRUE(),IF((Base_Dados!$C$2:$C$500=$B10)*(Base_Dados!$A$2:$A$500="Semana (2ª a 6ª)")*(Base_Dados!$B$2:$B$500="Noite"),Base_Dados!$E$2:$E$500,""))} | J10: {=_xlfn.TEXTJOIN(", ",TRUE(),IF((Base_Dados!$C$2:$C$500=$B10)*(Base_Dados!$A$2:$A$500="Sábado"),Base_Dados!$E$2:$E$500&" ("&Base_Dados!$B$2:$B$500&")",""))} -> 24-ZZ-64 (Manhã), CA-27-DS (Tarde) | K10: {=_xlfn.TEXTJOIN(", ",TRUE(),IF((Base_Dados!$C$2:$C$500=$B10)*(Base_Dados!$A$2:$A$500="Domingo"),Base_Dados!$E$2:$E$500&" ("&Base_Dados!$B$2:$B$500&")",""))} | L10: =COUNTIFS(Base_Dados!$C$2:$C$500,$B10,Base_Dados!$A$2:$A$500,"Semana (2ª a 6ª)") -> 2 | M10: =COUNTIF(Base_Dados!$C$2:$C$500,$B10) -> 4 | N10: =IF(M10=0,"Sem viatura atribuída",IF(L10=0,"Só ao fim de semana","OK")) -> OK
A11: Indiferenciados | B11: C7 | C11: PAP | D11: Donin Briteiros S. Estevão | E11: 3ª, 5ª & SAB | G11: {=_xlfn.TEXTJOIN(", ",TRUE(),IF((Base_Dados!$C$2:$C$500=$B11)*(Base_Dados!$A$2:$A$500="Semana (2ª a 6ª)")*(Base_Dados!$B$2:$B$500="Manhã"),Base_Dados!$E$2:$E$500,""))} -> 60-93-ZG | H11: {=_xlfn.TEXTJOIN(", ",TRUE(),IF((Base_Dados!$C$2:$C$500=$B11)*(Base_Dados!$A$2:$A$500="Semana (2ª a 6ª)")*(Base_Dados!$B$2:$B$500="Tarde"),Base_Dados!$E$2:$E$500,""))} | I11: {=_xlfn.TEXTJOIN(", ",TRUE(),IF((Base_Dados!$C$2:$C$500=$B11)*(Base_Dados!$A$2:$A$500="Semana (2ª a 6ª)")*(Base_Dados!$B$2:$B$500="Noite"),Base_Dados!$E$2:$E$500,""))} | J11: {=_xlfn.TEXTJOIN(", ",TRUE(),IF((Base_Dados!$C$2:$C$500=$B11)*(Base_Dados!$A$2:$A$500="Sábado"),Base_Dados!$E$2:$E$500&" ("&Base_Dados!$B$2:$B$500&")",""))} -> 60-93-ZG (Manhã) | K11: {=_xlfn.TEXTJOIN(", ",TRUE(),IF((Base_Dados!$C$2:$C$500=$B11)*(Base_Dados!$A$2:$A$500="Domingo"),Base_Dados!$E$2:$E$500&" ("&Base_Dados!$B$2:$B$500&")",""))} | L11: =COUNTIFS(Base_Dados!$C$2:$C$500,$B11,Base_Dados!$A$2:$A$500,"Semana (2ª a 6ª)") -> 1 | M11: =COUNTIF(Base_Dados!$C$2:$C$500,$B11) -> 2 | N11: =IF(M11=0,"Sem viatura atribuída",IF(L11=0,"Só ao fim de semana","OK")) -> OK
A12: Indiferenciados | B12: C8 | C12: PAP | D12: Ponte | E12: 4ª (manhã) 2ª & 6ª (tarde) | G12: {=_xlfn.TEXTJOIN(", ",TRUE(),IF((Base_Dados!$C$2:$C$500=$B12)*(Base_Dados!$A$2:$A$500="Semana (2ª a 6ª)")*(Base_Dados!$B$2:$B$500="Manhã"),Base_Dados!$E$2:$E$500,""))} | H12: {=_xlfn.TEXTJOIN(", ",TRUE(),IF((Base_Dados!$C$2:$C$500=$B12)*(Base_Dados!$A$2:$A$500="Semana (2ª a 6ª)")*(Base_Dados!$B$2:$B$500="Tarde"),Base_Dados!$E$2:$E$500,""))} | I12: {=_xlfn.TEXTJOIN(", ",TRUE(),IF((Base_Dados!$C$2:$C$500=$B12)*(Base_Dados!$A$2:$A$500="Semana (2ª a 6ª)")*(Base_Dados!$B$2:$B$500="Noite"),Base_Dados!$E$2:$E$500,""))} | J12: {=_xlfn.TEXTJOIN(", ",TRUE(),IF((Base_Dados!$C$2:$C$500=$B12)*(Base_Dados!$A$2:$A$500="Sábado"),Base_Dados!$E$2:$E$500&" ("&Base_Dados!$B$2:$B$500&")",""))} | K12: {=_xlfn.TEXTJOIN(", ",TRUE(),IF((Base_Dados!$C$2:$C$500=$B12)*(Base_Dados!$A$2:$A$500="Domingo"),Base_Dados!$E$2:$E$500&" ("&Base_Dados!$B$2:$B$500&")",""))} | L12: =COUNTIFS(Base_Dados!$C$2:$C$500,$B12,Base_Dados!$A$2:$A$500,"Semana (2ª a 6ª)") -> 0 | M12: =COUNTIF(Base_Dados!$C$2:$C$500,$B12) -> 0 | N12: =IF(M12=0,"Sem viatura atribuída",IF(L12=0,"Só ao fim de semana","OK")) -> Sem viatura atribuída
A13: Indiferenciados | B13: C9 | C13: PAP | D13: Balazar Longos Sande São Lourenço Santa Leocadia de Briteiros | E13: 2ª, 4ª & 6ª | G13: {=_xlfn.TEXTJOIN(", ",TRUE(),IF((Base_Dados!$C$2:$C$500=$B13)*(Base_Dados!$A$2:$A$500="Semana (2ª a 6ª)")*(Base_Dados!$B$2:$B$500="Manhã"),Base_Dados!$E$2:$E$500,""))} -> 49-GC-81 | H13: {=_xlfn.TEXTJOIN(", ",TRUE(),IF((Base_Dados!$C$2:$C$500=$B13)*(Base_Dados!$A$2:$A$500="Semana (2ª a 6ª)")*(Base_Dados!$B$2:$B$500="Tarde"),Base_Dados!$E$2:$E$500,""))} | I13: {=_xlfn.TEXTJOIN(", ",TRUE(),IF((Base_Dados!$C$2:$C$500=$B13)*(Base_Dados!$A$2:$A$500="Semana (2ª a 6ª)")*(Base_Dados!$B$2:$B$500="Noite"),Base_Dados!$E$2:$E$500,""))} | J13: {=_xlfn.TEXTJOIN(", ",TRUE(),IF((Base_Dados!$C$2:$C$500=$B13)*(Base_Dados!$A$2:$A$500="Sábado"),Base_Dados!$E$2:$E$500&" ("&Base_Dados!$B$2:$B$500&")",""))} -> 49-GC-81 (Manhã) | K13: {=_xlfn.TEXTJOIN(", ",TRUE(),IF((Base_Dados!$C$2:$C$500=$B13)*(Base_Dados!$A$2:$A$500="Domingo"),Base_Dados!$E$2:$E$500&" ("&Base_Dados!$B$2:$B$500&")",""))} | L13: =COUNTIFS(Base_Dados!$C$2:$C$500,$B13,Base_Dados!$A$2:$A$500,"Semana (2ª a 6ª)") -> 1 | M13: =COUNTIF(Base_Dados!$C$2:$C$500,$B13) -> 2 | N13: =IF(M13=0,"Sem viatura atribuída",IF(L13=0,"Só ao fim de semana","OK")) -> OK
A14: Indiferenciados | B14: C10 | C14: PAP | D14: Arosa Castelões Souto São Salvador Gondomar Souto Santa Maria | E14: 3ª, 5ª, & SAB. | G14: {=_xlfn.TEXTJOIN(", ",TRUE(),IF((Base_Dados!$C$2:$C$500=$B14)*(Base_Dados!$A$2:$A$500="Semana (2ª a 6ª)")*(Base_Dados!$B$2:$B$500="Manhã"),Base_Dados!$E$2:$E$500,""))} -> 49-GC-80 | H14: {=_xlfn.TEXTJOIN(", ",TRUE(),IF((Base_Dados!$C$2:$C$500=$B14)*(Base_Dados!$A$2:$A$500="Semana (2ª a 6ª)")*(Base_Dados!$B$2:$B$500="Tarde"),Base_Dados!$E$2:$E$500,""))} | I14: {=_xlfn.TEXTJOIN(", ",TRUE(),IF((Base_Dados!$C$2:$C$500=$B14)*(Base_Dados!$A$2:$A$500="Semana (2ª a 6ª)")*(Base_Dados!$B$2:$B$500="Noite"),Base_Dados!$E$2:$E$500,""))} | J14: {=_xlfn.TEXTJOIN(", ",TRUE(),IF((Base_Dados!$C$2:$C$500=$B14)*(Base_Dados!$A$2:$A$500="Sábado"),Base_Dados!$E$2:$E$500&" ("&Base_Dados!$B$2:$B$500&")",""))} -> 49-GC-80 (Manhã) | K14: {=_xlfn.TEXTJOIN(", ",TRUE(),IF((Base_Dados!$C$2:$C$500=$B14)*(Base_Dados!$A$2:$A$500="Domingo"),Base_Dados!$E$2:$E$500&" ("&Base_Dados!$B$2:$B$500&")",""))} | L14: =COUNTIFS(Base_Dados!$C$2:$C$500,$B14,Base_Dados!$A$2:$A$500,"Semana (2ª a 6ª)") -> 1 | M14: =COUNTIF(Base_Dados!$C$2:$C$500,$B14) -> 2 | N14: =IF(M14=0,"Sem viatura atribuída",IF(L14=0,"Só ao fim de semana","OK")) -> OK
A15: Indiferenciados | B15: C11 | C15: PAP | D15: Contentores Ponte ( 2º E 6º) Taipas Sande São Martinho São Salvador de Briteiros Nascional de Brito/taips Escolas Taipas Supermercado | E15: 2ª, 4ª, 6ª (manhã) 3ª, 5ª, SAB (tarde) | G15: {=_xlfn.TEXTJOIN(", ",TRUE(),IF((Base_Dados!$C$2:$C$500=$B15)*(Base_Dados!$A$2:$A$500="Semana (2ª a 6ª)")*(Base_Dados!$B$2:$B$500="Manhã"),Base_Dados!$E$2:$E$500,""))} -> 49-GC-80 | H15: {=_xlfn.TEXTJOIN(", ",TRUE(),IF((Base_Dados!$C$2:$C$500=$B15)*(Base_Dados!$A$2:$A$500="Semana (2ª a 6ª)")*(Base_Dados!$B$2:$B$500="Tarde"),Base_Dados!$E$2:$E$500,""))} | I15: {=_xlfn.TEXTJOIN(", ",TRUE(),IF((Base_Dados!$C$2:$C$500=$B15)*(Base_Dados!$A$2:$A$500="Semana (2ª a 6ª)")*(Base_Dados!$B$2:$B$500="Noite"),Base_Dados!$E$2:$E$500,""))} | J15: {=_xlfn.TEXTJOIN(", ",TRUE(),IF((Base_Dados!$C$2:$C$500=$B15)*(Base_Dados!$A$2:$A$500="Sábado"),Base_Dados!$E$2:$E$500&" ("&Base_Dados!$B$2:$B$500&")",""))} -> 49-GC-80 (Manhã) | K15: {=_xlfn.TEXTJOIN(", ",TRUE(),IF((Base_Dados!$C$2:$C$500=$B15)*(Base_Dados!$A$2:$A$500="Domingo"),Base_Dados!$E$2:$E$500&" ("&Base_Dados!$B$2:$B$500&")",""))} | L15: =COUNTIFS(Base_Dados!$C$2:$C$500,$B15,Base_Dados!$A$2:$A$500,"Semana (2ª a 6ª)") -> 1 | M15: =COUNTIF(Base_Dados!$C$2:$C$500,$B15) -> 2 | N15: =IF(M15=0,"Sem viatura atribuída",IF(L15=0,"Só ao fim de semana","OK")) -> OK
A16: Indiferenciados | B16: C12 | C16: PAP | D16: Santo Amaro Santiago Candoso Silvares | E16: 2ª, 4ª & 6ª | G16: {=_xlfn.TEXTJOIN(", ",TRUE(),IF((Base_Dados!$C$2:$C$500=$B16)*(Base_Dados!$A$2:$A$500="Semana (2ª a 6ª)")*(Base_Dados!$B$2:$B$500="Manhã"),Base_Dados!$E$2:$E$500,""))} | H16: {=_xlfn.TEXTJOIN(", ",TRUE(),IF((Base_Dados!$C$2:$C$500=$B16)*(Base_Dados!$A$2:$A$500="Semana (2ª a 6ª)")*(Base_Dados!$B$2:$B$500="Tarde"),Base_Dados!$E$2:$E$500,""))} | I16: {=_xlfn.TEXTJOIN(", ",TRUE(),IF((Base_Dados!$C$2:$C$500=$B16)*(Base_Dados!$A$2:$A$500="Semana (2ª a 6ª)")*(Base_Dados!$B$2:$B$500="Noite"),Base_Dados!$E$2:$E$500,""))} | J16: {=_xlfn.TEXTJOIN(", ",TRUE(),IF((Base_Dados!$C$2:$C$500=$B16)*(Base_Dados!$A$2:$A$500="Sábado"),Base_Dados!$E$2:$E$500&" ("&Base_Dados!$B$2:$B$500&")",""))} | K16: {=_xlfn.TEXTJOIN(", ",TRUE(),IF((Base_Dados!$C$2:$C$500=$B16)*(Base_Dados!$A$2:$A$500="Domingo"),Base_Dados!$E$2:$E$500&" ("&Base_Dados!$B$2:$B$500&")",""))} | L16: =COUNTIFS(Base_Dados!$C$2:$C$500,$B16,Base_Dados!$A$2:$A$500,"Semana (2ª a 6ª)") -> 0 | M16: =COUNTIF(Base_Dados!$C$2:$C$500,$B16) -> 0 | N16: =IF(M16=0,"Sem viatura atribuída",IF(L16=0,"Só ao fim de semana","OK")) -> Sem viatura atribuída
... A28: Indiferenciados | B28: C24 | C28: PAP | D28: Moreira de Conégos | E28: 3ª, 5ª & SAB | G28: {=_xlfn.TEXTJOIN(", ",TRUE(),IF((Base_Dados!$C$2:$C$500=$B28)*(Base_Dados!$A$2:$A$500="Semana (2ª a 6ª)")*(Base_Dados!$B$2:$B$500="Manhã"),Base_Dados!$E$2:$E$500,""))} | H28: {=_xlfn.TEXTJOIN(", ",TRUE(),IF((Base_Dados!$C$2:$C$500=$B28)*(Base_Dados!$A$2:$A$500="Semana (2ª a 6ª)")*(Base_Dados!$B$2:$B$500="Tarde"),Base_Dados!$E$2:$E$500,""))} | I28: {=_xlfn.TEXTJOIN(", ",TRUE(),IF((Base_Dados!$C$2:$C$500=$B28)*(Base_Dados!$A$2:$A$500="Semana (2ª a 6ª)")*(Base_Dados!$B$2:$B$500="Noite"),Base_Dados!$E$2:$E$500,""))} | J28: {=_xlfn.TEXTJOIN(", ",TRUE(),IF((Base_Dados!$C$2:$C$500=$B28)*(Base_Dados!$A$2:$A$500="Sábado"),Base_Dados!$E$2:$E$500&" ("&Base_Dados!$B$2:$B$500&")",""))} | K28: {=_xlfn.TEXTJOIN(", ",TRUE(),IF((Base_Dados!$C$2:$C$500=$B28)*(Base_Dados!$A$2:$A$500="Domingo"),Base_Dados!$E$2:$E$500&" ("&Base_Dados!$B$2:$B$500&")",""))} | L28: =COUNTIFS(Base_Dados!$C$2:$C$500,$B28,Base_Dados!$A$2:$A$500,"Semana (2ª a 6ª)") -> 0 | M28: =COUNTIF(Base_Dados!$C$2:$C$500,$B28) -> 0 | N28: =IF(M28=0,"Sem viatura atribuída",IF(L28=0,"Só ao fim de semana","OK")) -> Sem viatura atribuída

Sheet Recicláveis
A1: Circuitos · Recicláveis
A4: Tipologia | B4: Circuito | C4: Tipo de recolha | D4: Localidades | E4: Dias de recolha | F4: Cód. viatura (ficheiro circuitos) | G4: Semana · Manhã | H4: Semana · Tarde | I4: Semana · Noite | J4: Sábado | K4: Domingo | L4: Nº afetações (semana) | M4: Nº afetações (total) | N4: Estado | O4: Observação
A5: Recicláveis | B5: CARTÃO | G5: {=_xlfn.TEXTJOIN(", ",TRUE(),IF((Base_Dados!$C$2:$C$500=$B5)*(Base_Dados!$A$2:$A$500="Semana (2ª a 6ª)")*(Base_Dados!$B$2:$B$500="Manhã"),Base_Dados!$E$2:$E$500,""))} | H5: {=_xlfn.TEXTJOIN(", ",TRUE(),IF((Base_Dados!$C$2:$C$500=$B5)*(Base_Dados!$A$2:$A$500="Semana (2ª a 6ª)")*(Base_Dados!$B$2:$B$500="Tarde"),Base_Dados!$E$2:$E$500,""))} -> 24-ZZ-64 | I5: {=_xlfn.TEXTJOIN(", ",TRUE(),IF((Base_Dados!$C$2:$C$500=$B5)*(Base_Dados!$A$2:$A$500="Semana (2ª a 6ª)")*(Base_Dados!$B$2:$B$500="Noite"),Base_Dados!$E$2:$E$500,""))} | J5: {=_xlfn.TEXTJOIN(", ",TRUE(),IF((Base_Dados!$C$2:$C$500=$B5)*(Base_Dados!$A$2:$A$500="Sábado"),Base_Dados!$E$2:$E$500&" ("&Base_Dados!$B$2:$B$500&")",""))} -> 24-ZZ-64 (Tarde) | K5: {=_xlfn.TEXTJOIN(", ",TRUE(),IF((Base_Dados!$C$2:$C$500=$B5)*(Base_Dados!$A$2:$A$500="Domingo"),Base_Dados!$E$2:$E$500&" ("&Base_Dados!$B$2:$B$500&")",""))} | L5: =COUNTIFS(Base_Dados!$C$2:$C$500,$B5,Base_Dados!$A$2:$A$500,"Semana (2ª a 6ª)") -> 1 | M5: =COUNTIF(Base_Dados!$C$2:$C$500,$B5) -> 2 | N5: =IF(M5=0,"Sem viatura atribuída",IF(L5=0,"Só ao fim de semana","OK")) -> OK | O5: Não consta no ficheiro de circuitos.
A6: Recicláveis | B6: RECICLAGEM | G6: {=_xlfn.TEXTJOIN(", ",TRUE(),IF((Base_Dados!$C$2:$C$500=$B6)*(Base_Dados!$A$2:$A$500="Semana (2ª a 6ª)")*(Base_Dados!$B$2:$B$500="Manhã"),Base_Dados!$E$2:$E$500,""))} | H6: {=_xlfn.TEXTJOIN(", ",TRUE(),IF((Base_Dados!$C$2:$C$500=$B6)*(Base_Dados!$A$2:$A$500="Semana (2ª a 6ª)")*(Base_Dados!$B$2:$B$500="Tarde"),Base_Dados!$E$2:$E$500,""))} -> 75-ZQ-13 | I6: {=_xlfn.TEXTJOIN(", ",TRUE(),IF((Base_Dados!$C$2:$C$500=$B6)*(Base_Dados!$A$2:$A$500="Semana (2ª a 6ª)")*(Base_Dados!$B$2:$B$500="Noite"),Base_Dados!$E$2:$E$500,""))} | J6: {=_xlfn.TEXTJOIN(", ",TRUE(),IF((Base_Dados!$C$2:$C$500=$B6)*(Base_Dados!$A$2:$A$500="Sábado"),Base_Dados!$E$2:$E$500&" ("&Base_Dados!$B$2:$B$500&")",""))} -> 75-ZQ-13 (Tarde) | K6: {=_xlfn.TEXTJOIN(", ",TRUE(),IF((Base_Dados!$C$2:$C$500=$B6)*(Base_Dados!$A$2:$A$500="Domingo"),Base_Dados!$E$2:$E$500&" ("&Base_Dados!$B$2:$B$500&")",""))} | L6: =COUNTIFS(Base_Dados!$C$2:$C$500,$B6,Base_Dados!$A$2:$A$500,"Semana (2ª a 6ª)") -> 1 | M6: =COUNTIF(Base_Dados!$C$2:$C$500,$B6) -> 2 | N6: =IF(M6=0,"Sem viatura atribuída",IF(L6=0,"Só ao fim de semana","OK")) -> OK | O6: Não consta no ficheiro de circuitos.
A7: Recicláveis | B7: SELETIVO | G7: {=_xlfn.TEXTJOIN(", ",TRUE(),IF((Base_Dados!$C$2:$C$500=$B7)*(Base_Dados!$A$2:$A$500="Semana (2ª a 6ª)")*(Base_Dados!$B$2:$B$500="Manhã"),Base_Dados!$E$2:$E$500,""))} -> 65-RB-29 | H7: {=_xlfn.TEXTJOIN(", ",TRUE(),IF((Base_Dados!$C$2:$C$500=$B7)*(Base_Dados!$A$2:$A$500="Semana (2ª a 6ª)")*(Base_Dados!$B$2:$B$500="Tarde"),Base_Dados!$E$2:$E$500,""))} -> 47-LP-50, 75-ZQ-24 | I7: {=_xlfn.TEXTJOIN(", ",TRUE(),IF((Base_Dados!$C$2:$C$500=$B7)*(Base_Dados!$A$2:$A$500="Semana (2ª a 6ª)")*(Base_Dados!$B$2:$B$500="Noite"),Base_Dados!$E$2:$E$500,""))} | J7: {=_xlfn.TEXTJOIN(", ",TRUE(),IF((Base_Dados!$C$2:$C$500=$B7)*(Base_Dados!$A$2:$A$500="Sábado"),Base_Dados!$E$2:$E$500&" ("&Base_Dados!$B$2:$B$500&")",""))} -> 47-LP-50 (Tarde) | K7: {=_xlfn.TEXTJOIN(", ",TRUE(),IF((Base_Dados!$C$2:$C$500=$B7)*(Base_Dados!$A$2:$A$500="Domingo"),Base_Dados!$E$2:$E$500&" ("&Base_Dados!$B$2:$B$500&")",""))} | L7: =COUNTIFS(Base_Dados!$C$2:$C$500,$B7,Base_Dados!$A$2:$A$500,"Semana (2ª a 6ª)") -> 3 | M7: =COUNTIF(Base_Dados!$C$2:$C$500,$B7) -> 4 | N7: =IF(M7=0,"Sem viatura atribuída",IF(L7=0,"Só ao fim de semana","OK")) -> OK | O7: Não consta no ficheiro de circuitos.

Sheet Volumosos
A1: Circuitos · Volumosos (Monstros)
A4: Tipologia | B4: Circuito | C4: Tipo de recolha | D4: Localidades | E4: Dias de recolha | F4: Cód. viatura (ficheiro circuitos) | G4: Semana · Manhã | H4: Semana · Tarde | I4: Semana · Noite | J4: Sábado | K4: Domingo | L4: Nº afetações (semana) | M4: Nº afetações (total) | N4: Estado | O4: Observação
A5: Volumosos (Monstros) | B5: MONSTROS | G5: {=_xlfn.TEXTJOIN(", ",TRUE(),IF((Base_Dados!$C$2:$C$500=$B5)*(Base_Dados!$A$2:$A$500="Semana (2ª a 6ª)")*(Base_Dados!$B$2:$B$500="Manhã"),Base_Dados!$E$2:$E$500,""))} -> 60-45-XJ, 75-ZQ-24, 48-CQ-06, 75-ZQ-13 | H5: {=_xlfn.TEXTJOIN(", ",TRUE(),IF((Base_Dados!$C$2:$C$500=$B5)*(Base_Dados!$A$2:$A$500="Semana (2ª a 6ª)")*(Base_Dados!$B$2:$B$500="Tarde"),Base_Dados!$E$2:$E$500,""))} -> 48-CQ-06, 75-ZQ-24 | I5: {=_xlfn.TEXTJOIN(", ",TRUE(),IF((Base_Dados!$C$2:$C$500=$B5)*(Base_Dados!$A$2:$A$500="Semana (2ª a 6ª)")*(Base_Dados!$B$2:$B$500="Noite"),Base_Dados!$E$2:$E$500,""))} | J5: {=_xlfn.TEXTJOIN(", ",TRUE(),IF((Base_Dados!$C$2:$C$500=$B5)*(Base_Dados!$A$2:$A$500="Sábado"),Base_Dados!$E$2:$E$500&" ("&Base_Dados!$B$2:$B$500&")",""))} -> 60-45-XJ (Manhã), 75-ZQ-24 (Manhã), 48-CQ-06 (Manhã), 75-ZQ-24 (Tarde), 48-CQ-06 (Tarde) | K5: {=_xlfn.TEXTJOIN(", ",TRUE(),IF((Base_Dados!$C$2:$C$500=$B5)*(Base_Dados!$A$2:$A$500="Domingo"),Base_Dados!$E$2:$E$500&" ("&Base_Dados!$B$2:$B$500&")",""))} | L5: =COUNTIFS(Base_Dados!$C$2:$C$500,$B5,Base_Dados!$A$2:$A$500,"Semana (2ª a 6ª)") -> 6 | M5: =COUNTIF(Base_Dados!$C$2:$C$500,$B5) -> 11 | N5: =IF(M5=0,"Sem viatura atribuída",IF(L5=0,"Só ao fim de semana","OK")) -> OK | O5: Recolha de volumosos. Não consta no ficheiro de circuitos.

Sheet Outros serviços
A1: Circuitos · Outros serviços
A4: Tipologia | B4: Circuito | C4: Tipo de recolha | D4: Localidades | E4: Dias de recolha | F4: Cód. viatura (ficheiro circuitos) | G4: Semana · Manhã | H4: Semana · Tarde | I4: Semana · Noite | J4: Sábado | K4: Domingo | L4: Nº afetações (semana) | M4: Nº afetações (total) | N4: Estado | O4: Observação
A5: A confirmar | B5: 1A/1B | G5: {=_xlfn.TEXTJOIN(", ",TRUE(),IF((Base_Dados!$C$2:$C$500=$B5)*(Base_Dados!$A$2:$A$500="Semana (2ª a 6ª)")*(Base_Dados!$B$2:$B$500="Manhã"),Base_Dados!$E$2:$E$500,""))} -> 47-LP-50 | H5: {=_xlfn.TEXTJOIN(", ",TRUE(),IF((Base_Dados!$C$2:$C$500=$B5)*(Base_Dados!$A$2:$A$500="Semana (2ª a 6ª)")*(Base_Dados!$B$2:$B$500="Tarde"),Base_Dados!$E$2:$E$500,""))} | I5: {=_xlfn.TEXTJOIN(", ",TRUE(),IF((Base_Dados!$C$2:$C$500=$B5)*(Base_Dados!$A$2:$A$500="Semana (2ª a 6ª)")*(Base_Dados!$B$2:$B$500="Noite"),Base_Dados!$E$2:$E$500,""))} | J5: {=_xlfn.TEXTJOIN(", ",TRUE(),IF((Base_Dados!$C$2:$C$500=$B5)*(Base_Dados!$A$2:$A$500="Sábado"),Base_Dados!$E$2:$E$500&" ("&Base_Dados!$B$2:$B$500&")",""))} -> 47-LP-50 (Manhã) | K5: {=_xlfn.TEXTJOIN(", ",TRUE(),IF((Base_Dados!$C$2:$C$500=$B5)*(Base_Dados!$A$2:$A$500="Domingo"),Base_Dados!$E$2:$E$500&" ("&Base_Dados!$B$2:$B$500&")",""))} | L5: =COUNTIFS(Base_Dados!$C$2:$C$500,$B5,Base_Dados!$A$2:$A$500,"Semana (2ª a 6ª)") -> 1 | M5: =COUNTIF(Base_Dados!$C$2:$C$500,$B5) -> 2 | N5: =IF(M5=0,"Sem viatura atribuída",IF(L5=0,"Só ao fim de semana","OK")) -> OK | O5: Código "1 A/ 1B" não existe no ficheiro de circuitos. Confirmar.
A6: A confirmar | B6: C.H (Centro Histórico) | G6: {=_xlfn.TEXTJOIN(", ",TRUE(),IF((Base_Dados!$C$2:$C$500=$B6)*(Base_Dados!$A$2:$A$500="Semana (2ª a 6ª)")*(Base_Dados!$B$2:$B$500="Manhã"),Base_Dados!$E$2:$E$500,""))} | H6: {=_xlfn.TEXTJOIN(", ",TRUE(),IF((Base_Dados!$C$2:$C$500=$B6)*(Base_Dados!$A$2:$A$500="Semana (2ª a 6ª)")*(Base_Dados!$B$2:$B$500="Tarde"),Base_Dados!$E$2:$E$500,""))} | I6: {=_xlfn.TEXTJOIN(", ",TRUE(),IF((Base_Dados!$C$2:$C$500=$B6)*(Base_Dados!$A$2:$A$500="Semana (2ª a 6ª)")*(Base_Dados!$B$2:$B$500="Noite"),Base_Dados!$E$2:$E$500,""))} | J6: {=_xlfn.TEXTJOIN(", ",TRUE(),IF((Base_Dados!$C$2:$C$500=$B6)*(Base_Dados!$A$2:$A$500="Sábado"),Base_Dados!$E$2:$E$500&" ("&Base_Dados!$B$2:$B$500&")",""))} | K6: {=_xlfn.TEXTJOIN(", ",TRUE(),IF((Base_Dados!$C$2:$C$500=$B6)*(Base_Dados!$A$2:$A$500="Domingo"),Base_Dados!$E$2:$E$500&" ("&Base_Dados!$B$2:$B$500&")",""))} -> 58-PF-10 (Manhã) | L6: =COUNTIFS(Base_Dados!$C$2:$C$500,$B6,Base_Dados!$A$2:$A$500,"Semana (2ª a 6ª)") -> 0 | M6: =COUNTIF(Base_Dados!$C$2:$C$500,$B6) -> 1 | N6: =IF(M6=0,"Sem viatura atribuída",IF(L6=0,"Só ao fim de semana","OK")) -> Só ao fim de semana | O6: Escrito "C.H" no domingo. Pode ser BIO 1 (Centro histórico). Confirmar.
A7: Serviços de apoio | B7: CONTENTORES | G7: {=_xlfn.TEXTJOIN(", ",TRUE(),IF((Base_Dados!$C$2:$C$500=$B7)*(Base_Dados!$A$2:$A$500="Semana (2ª a 6ª)")*(Base_Dados!$B$2:$B$500="Manhã"),Base_Dados!$E$2:$E$500,""))} -> BZ-39-IV | H7: {=_xlfn.TEXTJOIN(", ",TRUE(),IF((Base_Dados!$C$2:$C$500=$B7)*(Base_Dados!$A$2:$A$500="Semana (2ª a 6ª)")*(Base_Dados!$B$2:$B$500="Tarde"),Base_Dados!$E$2:$E$500,""))} | I7: {=_xlfn.TEXTJOIN(", ",TRUE(),IF((Base_Dados!$C$2:$C$500=$B7)*(Base_Dados!$A$2:$A$500="Semana (2ª a 6ª)")*(Base_Dados!$B$2:$B$500="Noite"),Base_Dados!$E$2:$E$500,""))} | J7: {=_xlfn.TEXTJOIN(", ",TRUE(),IF((Base_Dados!$C$2:$C$500=$B7)*(Base_Dados!$A$2:$A$500="Sábado"),Base_Dados!$E$2:$E$500&" ("&Base_Dados!$B$2:$B$500&")",""))} -> BZ-39-IV (Manhã) | K7: {=_xlfn.TEXTJOIN(", ",TRUE(),IF((Base_Dados!$C$2:$C$500=$B7)*(Base_Dados!$A$2:$A$500="Domingo"),Base_Dados!$E$2:$E$500&" ("&Base_Dados!$B$2:$B$500&")",""))} | L7: =COUNTIFS(Base_Dados!$C$2:$C$500,$B7,Base_Dados!$A$2:$A$500,"Semana (2ª a 6ª)") -> 1 | M7: =COUNTIF(Base_Dados!$C$2:$C$500,$B7) -> 2 | N7: =IF(M7=0,"Sem viatura atribuída",IF(L7=0,"Só ao fim de semana","OK")) -> OK | O7: Serviço de apoio (colocação/reparação de contentores?). Confirmar.
A8: Serviços de apoio | B8: LAVAGEM CONTENTORES | G8: {=_xlfn.TEXTJOIN(", ",TRUE(),IF((Base_Dados!$C$2:$C$500=$B8)*(Base_Dados!$A$2:$A$500="Semana (2ª a 6ª)")*(Base_Dados!$B$2:$B$500="Manhã"),Base_Dados!$E$2:$E$500,""))} -> CA-05-PT | H8: {=_xlfn.TEXTJOIN(", ",TRUE(),IF((Base_Dados!$C$2:$C$500=$B8)*(Base_Dados!$A$2:$A$500="Semana (2ª a 6ª)")*(Base_Dados!$B$2:$B$500="Tarde"),Base_Dados!$E$2:$E$500,""))} -> CA-05-PT | I8: {=_xlfn.TEXTJOIN(", ",TRUE(),IF((Base_Dados!$C$2:$C$500=$B8)*(Base_Dados!$A$2:$A$500="Semana (2ª a 6ª)")*(Base_Dados!$B$2:$B$500="Noite"),Base_Dados!$E$2:$E$500,""))} | J8: {=_xlfn.TEXTJOIN(", ",TRUE(),IF((Base_Dados!$C$2:$C$500=$B8)*(Base_Dados!$A$2:$A$500="Sábado"),Base_Dados!$E$2:$E$500&" ("&Base_Dados!$B$2:$B$500&")",""))} | K8: {=_xlfn.TEXTJOIN(", ",TRUE(),IF((Base_Dados!$C$2:$C$500=$B8)*(Base_Dados!$A$2:$A$500="Domingo"),Base_Dados!$E$2:$E$500&" ("&Base_Dados!$B$2:$B$500&")",""))} | L8: =COUNTIFS(Base_Dados!$C$2:$C$500,$B8,Base_Dados!$A$2:$A$500,"Semana (2ª a 6ª)") -> 2 | M8: =COUNTIF(Base_Dados!$C$2:$C$500,$B8) -> 2 | N8: =IF(M8=0,"Sem viatura atribuída",IF(L8=0,"Só ao fim de semana","OK")) -> OK | O8: Escrito "LAVAGEM" e "LAVA-CONTENTORES" no planeamento.
A9: PAYT | B9: PAYT | G9: {=_xlfn.TEXTJOIN(", ",TRUE(),IF((Base_Dados!$C$2:$C$500=$B9)*(Base_Dados!$A$2:$A$500="Semana (2ª a 6ª)")*(Base_Dados!$B$2:$B$500="Manhã"),Base_Dados!$E$2:$E$500,""))} -> AT-98-PM | H9: {=_xlfn.TEXTJOIN(", ",TRUE(),IF((Base_Dados!$C$2:$C$500=$B9)*(Base_Dados!$A$2:$A$500="Semana (2ª a 6ª)")*(Base_Dados!$B$2:$B$500="Tarde"),Base_Dados!$E$2:$E$500,""))} -> AT-98-PM | I9: {=_xlfn.TEXTJOIN(", ",TRUE(),IF((Base_Dados!$C$2:$C$500=$B9)*(Base_Dados!$A$2:$A$500="Semana (2ª a 6ª)")*(Base_Dados!$B$2:$B$500="Noite"),Base_Dados!$E$2:$E$500,""))} -> AT-28-PM, 75-ZQ-13 | J9: {=_xlfn.TEXTJOIN(", ",TRUE(),IF((Base_Dados!$C$2:$C$500=$B9)*(Base_Dados!$A$2:$A$500="Sábado"),Base_Dados!$E$2:$E$500&" ("&Base_Dados!$B$2:$B$500&")",""))} -> AT-98-PM (Manhã), AT-98-PM (Tarde), AT-98-PM (Noite), 75-ZQ-13 (Noite) | K9: {=_xlfn.TEXTJOIN(", ",TRUE(),IF((Base_Dados!$C$2:$C$500=$B9)*(Base_Dados!$A$2:$A$500="Domingo"),Base_Dados!$E$2:$E$500&" ("&Base_Dados!$B$2:$B$500&")",""))} -> AN-50-LT (Manhã), AT-98-PM (Manhã), AT-98-PM (Tarde), AT-98-PM (Noite) | L9: =COUNTIFS(Base_Dados!$C$2:$C$500,$B9,Base_Dados!$A$2:$A$500,"Semana (2ª a 6ª)") -> 4 | M9: =COUNTIF(Base_Dados!$C$2:$C$500,$B9) -> 12 | N9: =IF(M9=0,"Sem viatura atribuída",IF(L9=0,"Só ao fim de semana","OK")) -> OK | O9: Pay-As-You-Throw (Centro Histórico, folha CHG). Não consta no ficheiro de circuitos.
A10: Sem afetação | B10: SEM CIRCUITO | G10: {=_xlfn.TEXTJOIN(", ",TRUE(),IF((Base_Dados!$C$2:$C$500=$B10)*(Base_Dados!$A$2:$A$500="Semana (2ª a 6ª)")*(Base_Dados!$B$2:$B$500="Manhã"),Base_Dados!$E$2:$E$500,""))} -> AJ-49-UO, 29-48-XU, 74-HN-36 | H10: {=_xlfn.TEXTJOIN(", ",TRUE(),IF((Base_Dados!$C$2:$C$500=$B10)*(Base_Dados!$A$2:$A$500="Semana (2ª a 6ª)")*(Base_Dados!$B$2:$B$500="Tarde"),Base_Dados!$E$2:$E$500,""))} | I10: {=_xlfn.TEXTJOIN(", ",TRUE(),IF((Base_Dados!$C$2:$C$500=$B10)*(Base_Dados!$A$2:$A$500="Semana (2ª a 6ª)")*(Base_Dados!$B$2:$B$500="Noite"),Base_Dados!$E$2:$E$500,""))} | J10: {=_xlfn.TEXTJOIN(", ",TRUE(),IF((Base_Dados!$C$2:$C$500=$B10)*(Base_Dados!$A$2:$A$500="Sábado"),Base_Dados!$E$2:$E$500&" ("&Base_Dados!$B$2:$B$500&")",""))} -> 65-RB-29 (Manhã), 29-48-XU (Manhã), 58-PF-10 (Manhã), AJ-49-UO (Manhã), 74-HN-36 (Manhã), 75-ZQ-13 (Manhã) | K10: {=_xlfn.TEXTJOIN(", ",TRUE(),IF((Base_Dados!$C$2:$C$500=$B10)*(Base_Dados!$A$2:$A$500="Domingo"),Base_Dados!$E$2:$E$500&" ("&Base_Dados!$B$2:$B$500&")",""))} -> 75-ZQ-24 (Manhã), 48-CQ-06 (Manhã) | L10: =COUNTIFS(Base_Dados!$C$2:$C$500,$B10,Base_Dados!$A$2:$A$500,"Semana (2ª a 6ª)") -> 3 | M10: =COUNTIF(Base_Dados!$C$2:$C$500,$B10) -> 11 | N10: — | O10: Viaturas listadas no planeamento sem circuito atribuído (reserva/oficina?).

Sheet Viaturas
A1: Viaturas · circuitos atribuídos por turno
A4: Matrícula | B4: Semana · Manhã | C4: Semana · Tarde | D4: Semana · Noite | E4: Sábado | F4: Domingo | G4: Turnos ocupados (semana) | H4: Afetações (total) | I4: Observação
A5: 24-ZZ-64 | B5: {=_xlfn.TEXTJOIN(", ",TRUE(),IF((Base_Dados!$E$2:$E$500=$A5)*(Base_Dados!$A$2:$A$500="Semana (2ª a 6ª)")*(Base_Dados!$B$2:$B$500="Manhã"),Base_Dados!$C$2:$C$500,""))} -> C6 | C5: {=_xlfn.TEXTJOIN(", ",TRUE(),IF((Base_Dados!$E$2:$E$500=$A5)*(Base_Dados!$A$2:$A$500="Semana (2ª a 6ª)")*(Base_Dados!$B$2:$B$500="Tarde"),Base_Dados!$C$2:$C$500,""))} -> CARTÃO | D5: {=_xlfn.TEXTJOIN(", ",TRUE(),IF((Base_Dados!$E$2:$E$500=$A5)*(Base_Dados!$A$2:$A$500="Semana (2ª a 6ª)")*(Base_Dados!$B$2:$B$500="Noite"),Base_Dados!$C$2:$C$500,""))} | E5: {=_xlfn.TEXTJOIN(", ",TRUE(),IF((Base_Dados!$E$2:$E$500=$A5)*(Base_Dados!$A$2:$A$500="Sábado"),Base_Dados!$C$2:$C$500&" ("&Base_Dados!$B$2:$B$500&")",""))} -> C6 (Manhã), CARTÃO (Tarde) | F5: {=_xlfn.TEXTJOIN(", ",TRUE(),IF((Base_Dados!$E$2:$E$500=$A5)*(Base_Dados!$A$2:$A$500="Domingo"),Base_Dados!$C$2:$C$500&" ("&Base_Dados!$B$2:$B$500&")",""))} | G5: =(COUNTIFS(Base_Dados!$E$2:$E$500,$A5,Base_Dados!$A$2:$A$500,"Semana (2ª a 6ª)",Base_Dados!$B$2:$B$500,"Manhã",Base_Dados!$C$2:$C$500,"<>SEM CIRCUITO")>0)+(COUNTIFS(Base_Dados!$E$2:$E$500,$A5,Base_Dados!$A$2:$A$500,"Semana (2ª a 6ª)",Base_Dados!$B$2:$B$500,"Tarde",Base_Dados!$C$2:$C$500,"<>SEM CIRCUITO")>0)+(COUNTIFS(Base_Dados!$E$2:$E$500,$A5,Base_Dados!$A$2:$A$500,"Semana (2ª a 6ª)",Base_Dados!$B$2:$B$500,"Noite",Base_Dados!$C$2:$C$500,"<>SEM CIRCUITO")>0) -> 2 | H5: =COUNTIFS(Base_Dados!$E$2:$E$500,$A5,Base_Dados!$C$2:$C$500,"<>SEM CIRCUITO") -> 4
A6: 29-20-ZN | B6: {=_xlfn.TEXTJOIN(", ",TRUE(),IF((Base_Dados!$E$2:$E$500=$A6)*(Base_Dados!$A$2:$A$500="Semana (2ª a 6ª)")*(Base_Dados!$B$2:$B$500="Manhã"),Base_Dados!$C$2:$C$500,""))} -> C16, C17 | C6: {=_xlfn.TEXTJOIN(", ",TRUE(),IF((Base_Dados!$E$2:$E$500=$A6)*(Base_Dados!$A$2:$A$500="Semana (2ª a 6ª)")*(Base_Dados!$B$2:$B$500="Tarde"),Base_Dados!$C$2:$C$500,""))} | D6: {=_xlfn.TEXTJOIN(", ",TRUE(),IF((Base_Dados!$E$2:$E$500=$A6)*(Base_Dados!$A$2:$A$500="Semana (2ª a 6ª)")*(Base_Dados!$B$2:$B$500="Noite"),Base_Dados!$C$2:$C$500,""))} | E6: {=_xlfn.TEXTJOIN(", ",TRUE(),IF((Base_Dados!$E$2:$E$500=$A6)*(Base_Dados!$A$2:$A$500="Sábado"),Base_Dados!$C$2:$C$500&" ("&Base_Dados!$B$2:$B$500&")",""))} -> C16 (Manhã), C17 (Manhã) | F6: {=_xlfn.TEXTJOIN(", ",TRUE(),IF((Base_Dados!$E$2:$E$500=$A6)*(Base_Dados!$A$2:$A$500="Domingo"),Base_Dados!$C$2:$C$500&" ("&Base_Dados!$B$2:$B$500&")",""))} | G6: =(COUNTIFS(Base_Dados!$E$2:$E$500,$A6,Base_Dados!$A$2:$A$500,"Semana (2ª a 6ª)",Base_Dados!$B$2:$B$500,"Manhã",Base_Dados!$C$2:$C$500,"<>SEM CIRCUITO")>0)+(COUNTIFS(Base_Dados!$E$2:$E$500,$A6,Base_Dados!$A$2:$A$500,"Semana (2ª a 6ª)",Base_Dados!$B$2:$B$500,"Tarde",Base_Dados!$C$2:$C$500,"<>SEM CIRCUITO")>0)+(COUNTIFS(Base_Dados!$E$2:$E$500,$A6,Base_Dados!$A$2:$A$500,"Semana (2ª a 6ª)",Base_Dados!$B$2:$B$500,"Noite",Base_Dados!$C$2:$C$500,"<>SEM CIRCUITO")>0) -> 1 | H6: =COUNTIFS(Base_Dados!$E$2:$E$500,$A6,Base_Dados!$C$2:$C$500,"<>SEM CIRCUITO") -> 4
A7: 29-48-XU | B7: {=_xlfn.TEXTJOIN(", ",TRUE(),IF((Base_Dados!$E$2:$E$500=$A7)*(Base_Dados!$A$2:$A$500="Semana (2ª a 6ª)")*(Base_Dados!$B$2:$B$500="Manhã"),Base_Dados!$C$2:$C$500,""))} -> SEM CIRCUITO | C7: {=_xlfn.TEXTJOIN(", ",TRUE(),IF((Base_Dados!$E$2:$E$500=$A7)*(Base_Dados!$A$2:$A$500="Semana (2ª a 6ª)")*(Base_Dados!$B$2:$B$500="Tarde"),Base_Dados!$C$2:$C$500,""))} | D7: {=_xlfn.TEXTJOIN(", ",TRUE(),IF((Base_Dados!$E$2:$E$500=$A7)*(Base_Dados!$A$2:$A$500="Semana (2ª a 6ª)")*(Base_Dados!$B$2:$B$500="Noite"),Base_Dados!$C$2:$C$500,""))} | E7: {=_xlfn.TEXTJOIN(", ",TRUE(),IF((Base_Dados!$E$2:$E$500=$A7)*(Base_Dados!$A$2:$A$500="Sábado"),Base_Dados!$C$2:$C$500&" ("&Base_Dados!$B$2:$B$500&")",""))} -> SEM CIRCUITO (Manhã) | F7: {=_xlfn.TEXTJOIN(", ",TRUE(),IF((Base_Dados!$E$2:$E$500=$A7)*(Base_Dados!$A$2:$A$500="Domingo"),Base_Dados!$C$2:$C$500&" ("&Base_Dados!$B$2:$B$500&")",""))} | G7: =(COUNTIFS(Base_Dados!$E$2:$E$500,$A7,Base_Dados!$A$2:$A$500,"Semana (2ª a 6ª)",Base_Dados!$B$2:$B$500,"Manhã",Base_Dados!$C$2:$C$500,"<>SEM CIRCUITO")>0)+(COUNTIFS(Base_Dados!$E$2:$E$500,$A7,Base_Dados!$A$2:$A$500,"Semana (2ª a 6ª)",Base_Dados!$B$2:$B$500,"Tarde",Base_Dados!$C$2:$C$500,"<>SEM CIRCUITO")>0)+(COUNTIFS(Base_Dados!$E$2:$E$500,$A7,Base_Dados!$A$2:$A$500,"Semana (2ª a 6ª)",Base_Dados!$B$2:$B$500,"Noite",Base_Dados!$C$2:$C$500,"<>SEM CIRCUITO")>0) -> 0 | H7: =COUNTIFS(Base_Dados!$E$2:$E$500,$A7,Base_Dados!$C$2:$C$500,"<>SEM CIRCUITO") -> 0 | I7: Nunca tem circuito atribuído.
A8: 47-LP-50 | B8: {=_xlfn.TEXTJOIN(", ",TRUE(),IF((Base_Dados!$E$2:$E$500=$A8)*(Base_Dados!$A$2:$A$500="Semana (2ª a 6ª)")*(Base_Dados!$B$2:$B$500="Manhã"),Base_Dados!$C$2:$C$500,""))} -> 1A/1B | C8: {=_xlfn.TEXTJOIN(", ",TRUE(),IF((Base_Dados!$E$2:$E$500=$A8)*(Base_Dados!$A$2:$A$500="Semana (2ª a 6ª)")*(Base_Dados!$B$2:$B$500="Tarde"),Base_Dados!$C$2:$C$500,""))} -> SELETIVO | D8: {=_xlfn.TEXTJOIN(", ",TRUE(),IF((Base_Dados!$E$2:$E$500=$A8)*(Base_Dados!$A$2:$A$500="Semana (2ª a 6ª)")*(Base_Dados!$B$2:$B$500="Noite"),Base_Dados!$C$2:$C$500,""))} | E8: {=_xlfn.TEXTJOIN(", ",TRUE(),IF((Base_Dados!$E$2:$E$500=$A8)*(Base_Dados!$A$2:$A$500="Sábado"),Base_Dados!$C$2:$C$500&" ("&Base_Dados!$B$2:$B$500&")",""))} -> 1A/1B (Manhã), SELETIVO (Tarde) | F8: {=_xlfn.TEXTJOIN(", ",TRUE(),IF((Base_Dados!$E$2:$E$500=$A8)*(Base_Dados!$A$2:$A$500="Domingo"),Base_Dados!$C$2:$C$500&" ("&Base_Dados!$B$2:$B$500&")",""))} | G8: =(COUNTIFS(Base_Dados!$E$2:$E$500,$A8,Base_Dados!$A$2:$A$500,"Semana (2ª a 6ª)",Base_Dados!$B$2:$B$500,"Manhã",Base_Dados!$C$2:$C$500,"<>SEM CIRCUITO")>0)+(COUNTIFS(Base_Dados!$E$2:$E$500,$A8,Base_Dados!$A$2:$A$500,"Semana (2ª a 6ª)",Base_Dados!$B$2:$B$500,"Tarde",Base_Dados!$C$2:$C$500,"<>SEM CIRCUITO")>0)+(COUNTIFS(Base_Dados!$E$2:$E$500,$A8,Base_Dados!$A$2:$A$500,"Semana (2ª a 6ª)",Base_Dados!$B$2:$B$500,"Noite",Base_Dados!$C$2:$C$500,"<>SEM CIRCUITO")>0) -> 2 | H8: =COUNTIFS(Base_Dados!$E$2:$E$500,$A8,Base_Dados!$C$2:$C$500,"<>SEM CIRCUITO") -> 4
A9: 48-CQ-06 | B9: {=_xlfn.TEXTJOIN(", ",TRUE(),IF((Base_Dados!$E$2:$E$500=$A9)*(Base_Dados!$A$2:$A$500="Semana (2ª a 6ª)")*(Base_Dados!$B$2:$B$500="Manhã"),Base_Dados!$C$2:$C$500,""))} -> MONSTROS | C9: {=_xlfn.TEXTJOIN(", ",TRUE(),IF((Base_Dados!$E$2:$E$500=$A9)*(Base_Dados!$A$2:$A$500="Semana (2ª a 6ª)")*(Base_Dados!$B$2:$B$500="Tarde"),Base_Dados!$C$2:$C$500,""))} -> MONSTROS | D9: {=_xlfn.TEXTJOIN(", ",TRUE(),IF((Base_Dados!$E$2:$E$500=$A9)*(Base_Dados!$A$2:$A$500="Semana (2ª a 6ª)")*(Base_Dados!$B$2:$B$500="Noite"),Base_Dados!$C$2:$C$500,""))} | E9: {=_xlfn.TEXTJOIN(", ",TRUE(),IF((Base_Dados!$E$2:$E$500=$A9)*(Base_Dados!$A$2:$A$500="Sábado"),Base_Dados!$C$2:$C$500&" ("&Base_Dados!$B$2:$B$500&")",""))} -> MONSTROS (Manhã), MONSTROS (Tarde) | F9: {=_xlfn.TEXTJOIN(", ",TRUE(),IF((Base_Dados!$E$2:$E$500=$A9)*(Base_Dados!$A$2:$A$500="Domingo"),Base_Dados!$C$2:$C$500&" ("&Base_Dados!$B$2:$B$500&")",""))} -> SEM CIRCUITO (Manhã) | G9: =(COUNTIFS(Base_Dados!$E$2:$E$500,$A9,Base_Dados!$A$2:$A$500,"Semana (2ª a 6ª)",Base_Dados!$B$2:$B$500,"Manhã",Base_Dados!$C$2:$C$500,"<>SEM CIRCUITO")>0)+(COUNTIFS(Base_Dados!$E$2:$E$500,$A9,Base_Dados!$A$2:$A$500,"Semana (2ª a 6ª)",Base_Dados!$B$2:$B$500,"Tarde",Base_Dados!$C$2:$C$500,"<>SEM CIRCUITO")>0)+(COUNTIFS(Base_Dados!$E$2:$E$500,$A9,Base_Dados!$A$2:$A$500,"Semana (2ª a 6ª)",Base_Dados!$B$2:$B$500,"Noite",Base_Dados!$C$2:$C$500,"<>SEM CIRCUITO")>0) -> 2 | H9: =COUNTIFS(Base_Dados!$E$2:$E$500,$A9,Base_Dados!$C$2:$C$500,"<>SEM CIRCUITO") -> 4
A10: 49-GC-79 | B10: {=_xlfn.TEXTJOIN(", ",TRUE(),IF((Base_Dados!$E$2:$E$500=$A10)*(Base_Dados!$A$2:$A$500="Semana (2ª a 6ª)")*(Base_Dados!$B$2:$B$500="Manhã"),Base_Dados!$C$2:$C$500,""))} -> C18, C19 | C10: {=_xlfn.TEXTJOIN(", ",TRUE(),IF((Base_Dados!$E$2:$E$500=$A10)*(Base_Dados!$A$2:$A$500="Semana (2ª a 6ª)")*(Base_Dados!$B$2:$B$500="Tarde"),Base_Dados!$C$2:$C$500,""))} | D10: {=_xlfn.TEXTJOIN(", ",TRUE(),IF((Base_Dados!$E$2:$E$500=$A10)*(Base_Dados!$A$2:$A$500="Semana (2ª a 6ª)")*(Base_Dados!$B$2:$B$500="Noite"),Base_Dados!$C$2:$C$500,""))} | E10: {=_xlfn.TEXTJOIN(", ",TRUE(),IF((Base_Dados!$E$2:$E$500=$A10)*(Base_Dados!$A$2:$A$500="Sábado"),Base_Dados!$C$2:$C$500&" ("&Base_Dados!$B$2:$B$500&")",""))} -> C18 (Manhã), C19 (Manhã) | F10: {=_xlfn.TEXTJOIN(", ",TRUE(),IF((Base_Dados!$E$2:$E$500=$A10)*(Base_Dados!$A$2:$A$500="Domingo"),Base_Dados!$C$2:$C$500&" ("&Base_Dados!$B$2:$B$500&")",""))} | G10: =(COUNTIFS(Base_Dados!$E$2:$E$500,$A10,Base_Dados!$A$2:$A$500,"Semana (2ª a 6ª)",Base_Dados!$B$2:$B$500,"Manhã",Base_Dados!$C$2:$C$500,"<>SEM CIRCUITO")>0)+(COUNTIFS(Base_Dados!$E$2:$E$500,$A10,Base_Dados!$A$2:$A$500,"Semana (2ª a 6ª)",Base_Dados!$B$2:$B$500,"Tarde",Base_Dados!$C$2:$C$500,"<>SEM CIRCUITO")>0)+(COUNTIFS(Base_Dados!$E$2:$E$500,$A10,Base_Dados!$A$2:$A$500,"Semana (2ª a 6ª)",Base_Dados!$B$2:$B$500,"Noite",Base_Dados!$C$2:$C$500,"<>SEM CIRCUITO")>0) -> 1 | H10: =COUNTIFS(Base_Dados!$E$2:$E$500,$A10,Base_Dados!$C$2:$C$500,"<>SEM CIRCUITO") -> 4
A11: 49-GC-80 | B11: {=_xlfn.TEXTJOIN(", ",TRUE(),IF((Base_Dados!$E$2:$E$500=$A11)*(Base_Dados!$A$2:$A$500="Semana (2ª a 6ª)")*(Base_Dados!$B$2:$B$500="Manhã"),Base_Dados!$C$2:$C$500,""))} -> C10, C11 | C11: {=_xlfn.TEXTJOIN(", ",TRUE(),IF((Base_Dados!$E$2:$E$500=$A11)*(Base_Dados!$A$2:$A$500="Semana (2ª a 6ª)")*(Base_Dados!$B$2:$B$500="Tarde"),Base_Dados!$C$2:$C$500,""))} | D11: {=_xlfn.TEXTJOIN(", ",TRUE(),IF((Base_Dados!$E$2:$E$500=$A11)*(Base_Dados!$A$2:$A$500="Semana (2ª a 6ª)")*(Base_Dados!$B$2:$B$500="Noite"),Base_Dados!$C$2:$C$500,""))} | E11: {=_xlfn.TEXTJOIN(", ",TRUE(),IF((Base_Dados!$E$2:$E$500=$A11)*(Base_Dados!$A$2:$A$500="Sábado"),Base_Dados!$C$2:$C$500&" ("&Base_Dados!$B$2:$B$500&")",""))} -> C10 (Manhã), C11 (Manhã) | F11: {=_xlfn.TEXTJOIN(", ",TRUE(),IF((Base_Dados!$E$2:$E$500=$A11)*(Base_Dados!$A$2:$A$500="Domingo"),Base_Dados!$C$2:$C$500&" ("&Base_Dados!$B$2:$B$500&")",""))} | G11: =(COUNTIFS(Base_Dados!$E$2:$E$500,$A11,Base_Dados!$A$2:$A$500,"Semana (2ª a 6ª)",Base_Dados!$B$2:$B$500,"Manhã",Base_Dados!$C$2:$C$500,"<>SEM CIRCUITO")>0)+(COUNTIFS(Base_Dados!$E$2:$E$500,$A11,Base_Dados!$A$2:$A$500,"Semana (2ª a 6ª)",Base_Dados!$B$2:$B$500,"Tarde",Base_Dados!$C$2:$C$500,"<>SEM CIRCUITO")>0)+(COUNTIFS(Base_Dados!$E$2:$E$500,$A11,Base_Dados!$A$2:$A$500,"Semana (2ª a 6ª)",Base_Dados!$B$2:$B$500,"Noite",Base_Dados!$C$2:$C$500,"<>SEM CIRCUITO")>0) -> 1 | H11: =COUNTIFS(Base_Dados!$E$2:$E$500,$A11,Base_Dados!$C$2:$C$500,"<>SEM CIRCUITO") -> 4
A12: 49-GC-81 | B12: {=_xlfn.TEXTJOIN(", ",TRUE(),IF((Base_Dados!$E$2:$E$500=$A12)*(Base_Dados!$A$2:$A$500="Semana (2ª a 6ª)")*(Base_Dados!$B$2:$B$500="Manhã"),Base_Dados!$C$2:$C$500,""))} -> C9 | C12: {=_xlfn.TEXTJOIN(", ",TRUE(),IF((Base_Dados!$E$2:$E$500=$A12)*(Base_Dados!$A$2:$A$500="Semana (2ª a 6ª)")*(Base_Dados!$B$2:$B$500="Tarde"),Base_Dados!$C$2:$C$500,""))} | D12: {=_xlfn.TEXTJOIN(", ",TRUE(),IF((Base_Dados!$E$2:$E$500=$A12)*(Base_Dados!$A$2:$A$500="Semana (2ª a 6ª)")*(Base_Dados!$B$2:$B$500="Noite"),Base_Dados!$C$2:$C$500,""))} | E12: {=_xlfn.TEXTJOIN(", ",TRUE(),IF((Base_Dados!$E$2:$E$500=$A12)*(Base_Dados!$A$2:$A$500="Sábado"),Base_Dados!$C$2:$C$500&" ("&Base_Dados!$B$2:$B$500&")",""))} -> C9 (Manhã) | F12: {=_xlfn.TEXTJOIN(", ",TRUE(),IF((Base_Dados!$E$2:$E$500=$A12)*(Base_Dados!$A$2:$A$500="Domingo"),Base_Dados!$C$2:$C$500&" ("&Base_Dados!$B$2:$B$500&")",""))} | G12: =(COUNTIFS(Base_Dados!$E$2:$E$500,$A12,Base_Dados!$A$2:$A$500,"Semana (2ª a 6ª)",Base_Dados!$B$2:$B$500,"Manhã",Base_Dados!$C$2:$C$500,"<>SEM CIRCUITO")>0)+(COUNTIFS(Base_Dados!$E$2:$E$500,$A12,Base_Dados!$A$2:$A$500,"Semana (2ª a 6ª)",Base_Dados!$B$2:$B$500,"Tarde",Base_Dados!$C$2:$C$500,"<>SEM CIRCUITO")>0)+(COUNTIFS(Base_Dados!$E$2:$E$500,$A12,Base_Dados!$A$2:$A$500,"Semana (2ª a 6ª)",Base_Dados!$B$2:$B$500,"Noite",Base_Dados!$C$2:$C$500,"<>SEM CIRCUITO")>0) -> 1 | H12: =COUNTIFS(Base_Dados!$E$2:$E$500,$A12,Base_Dados!$C$2:$C$500,"<>SEM CIRCUITO") -> 2
A13: 58-PF-10 | B13: {=_xlfn.TEXTJOIN(", ",TRUE(),IF((Base_Dados!$E$2:$E$500=$A13)*(Base_Dados!$A$2:$A$500="Semana (2ª a 6ª)")*(Base_Dados!$B$2:$B$500="Manhã"),Base_Dados!$C$2:$C$500,""))} -> BIO (s/ nº) | C13: {=_xlfn.TEXTJOIN(", ",TRUE(),IF((Base_Dados!$E$2:$E$500=$A13)*(Base_Dados!$A$2:$A$500="Semana (2ª a 6ª)")*(Base_Dados!$B$2:$B$500="Tarde"),Base_Dados!$C$2:$C$500,""))} | D13: {=_xlfn.TEXTJOIN(", ",TRUE(),IF((Base_Dados!$E$2:$E$500=$A13)*(Base_Dados!$A$2:$A$500="Semana (2ª a 6ª)")*(Base_Dados!$B$2:$B$500="Noite"),Base_Dados!$C$2:$C$500,""))} | E13: {=_xlfn.TEXTJOIN(", ",TRUE(),IF((Base_Dados!$E$2:$E$500=$A13)*(Base_Dados!$A$2:$A$500="Sábado"),Base_Dados!$C$2:$C$500&" ("&Base_Dados!$B$2:$B$500&")",""))} -> SEM CIRCUITO (Manhã) | F13: {=_xlfn.TEXTJOIN(", ",TRUE(),IF((Base_Dados!$E$2:$E$500=$A13)*(Base_Dados!$A$2:$A$500="Domingo"),Base_Dados!$C$2:$C$500&" ("&Base_Dados!$B$2:$B$500&")",""))} -> C.H (Centro Histórico) (Manhã) | G13: =(COUNTIFS(Base_Dados!$E$2:$E$500,$A13,Base_Dados!$A$2:$A$500,"Semana (2ª a 6ª)",Base_Dados!$B$2:$B$500,"Manhã",Base_Dados!$C$2:$C$500,"<>SEM CIRCUITO")>0)+(COUNTIFS(Base_Dados!$E$2:$E$500,$A13,Base_Dados!$A$2:$A$500,"Semana (2ª a 6ª)",Base_Dados!$B$2:$B$500,"Tarde",Base_Dados!$C$2:$C$500,"<>SEM CIRCUITO")>0)+(COUNTIFS(Base_Dados!$E$2:$E$500,$A13,Base_Dados!$A$2:$A$500,"Semana (2ª a 6ª)",Base_Dados!$B$2:$B$500,"Noite",Base_Dados!$C$2:$C$500,"<>SEM CIRCUITO")>0) -> 1 | H13: =COUNTIFS(Base_Dados!$E$2:$E$500,$A13,Base_Dados!$C$2:$C$500,"<>SEM CIRCUITO") -> 2
